Workbook
Name ky_ten: Assumption!$D$6
Name ky_bat_dau: Assumption!$D$7
Name ky_ket_thuc: Assumption!$D$8
Name tygia_usd_vnd: Assumption!$D$9
Name rate_muc1: Assumption!$D$13
Name rate_muc2: Assumption!$D$14
Name rate_muc3: Assumption!$D$15
Name khmoi_step: Assumption!$D$16
Name khmoi_step_x2: Assumption!$D$17
Name khmoi_step_x3: Assumption!$D$18
Name incentive_floor: Assumption!$D$19
Name rate_bpsale: Assumption!$D$20
Name bpsale_step_cong: Assumption!$D$21
Name bpsale_step_tru: Assumption!$D$22
Name bpsale_cap_cong: Assumption!$D$23
Name bpsale_cap_tru: Assumption!$D$24
Name head_ma_nv: Assumption!$D$25
Name head_bonus_apply: Assumption!$D$26
Name pool_kae_admin: Assumption!$D$30
Name pool_kae_sale: Assumption!$D$31
Name rate_bo: Assumption!$D$32
Name phat_no_ratio: Assumption!$D$36
Name phat_60plus_giam: Assumption!$D$37
Name giam_tru_ca_nhan_quy: Assumption!$D$41
Name giam_tru_phu_thuoc_quy: Assumption!$D$42

Sheet Assumption
B2: BẢNG THAM SỐ INCENTIVE — Q1/2026
B4: 1. KỲ TÍNH
B5: STT | C5: Mô tả | D5: Giá trị | E5: Đơn vị | F5: Ghi chú / Công thức | G5: Named Range
B6: 1 | C6: Kỳ tính (tên) | E6: text | F6: Nhãn kỳ báo cáo | G6: ky_ten
B7: 2 | C7: Ngày bắt đầu | E7: date | G7: ky_bat_dau
B8: 3 | C8: Ngày kết thúc | E8: date | G8: ky_ket_thuc
B9: 4 | C9: Tỷ giá USD/VND | D9: 26000 | E9: VND | F9: Ngày lập bảng | G9: tygia_usd_vnd
B11: 2. RATE INCENTIVE (SALE COM)
B12: STT | C12: Mô tả | D12: Giá trị | E12: Đơn vị | F12: Ghi chú / Công thức | G12: Named Range
B13: 1 | C13: Rate mức 1 - KH đã bàn giao KAE (B1) | D13: 0.08 | E13: % | F13: Profit paid nhóm B1 | G13: rate_muc1
B14: 2 | C14: Rate mức 2 - KH chưa bàn giao KAE (B2) | D14: 0.12 | E14: % | F14: Profit paid nhóm B2 | G14: rate_muc2
B15: 3 | C15: Rate mức 3 - KH mới ≤6 tháng | D15: 0.17 | E15: % | F15: Profit paid KH mới | G15: rate_muc3
B16: 4 | C16: Bước điều chỉnh KH mới (±) | D16: 0.01 | E16: % | F16: Mỗi KH lệch chỉ tiêu = ±1% | G16: khmoi_step
B17: 5 | C17: Bước x2 (dự phòng) | D17: 0.02 | E17: % | F17: Chưa dùng | G17: khmoi_step_x2
B18: 6 | C18: Bước x3 (dự phòng) | D18: 0.03 | E18: % | F18: Chưa dùng | G18: khmoi_step_x3
B19: 7 | C19: Sàn incentive (floor) | D19: 0 | E19: VND | F19: Incentive không âm | G19: incentive_floor
B20: 8 | C20: Rate thưởng Trưởng BP (base) | D20: 0.024 | E20: % | F20: 2.4% × Sum_Vuot toàn BP (trừ Head) | G20: rate_bpsale
B21: 9 | C21: Step CỘNG (dư KH mới) / KH | D21: 0.002 | E21: % | F21: +0.2% mỗi KH dư chỉ tiêu | G21: bpsale_step_cong
B22: 10 | C22: Step TRỪ (thiếu KH mới) / KH | D22: 0.001 | E22: % | F22: -0.1% mỗi KH thiếu (asymmetric) | G22: bpsale_step_tru
B23: 11 | C23: Cap CỘNG (dư KH mới) | D23: 0.024 | E23: % | F23: Tối đa +2.4% / quý (12 KH dư) | G23: bpsale_cap_cong
B24: 12 | C24: Cap TRỪ (thiếu KH mới) | D24: 0.006 | E24: % | F24: Tối đa -0.6% / quý (6 KH thiếu × 0.1%) | G24: bpsale_cap_tru
B25: 13 | C25: Mã NV Trưởng BP KD | D25: TTN22.005 | E25: text | F25: Đổi mã khi thay Head | G25: head_ma_nv
B26: 14 | C26: Head Bonus áp dụng (1/0) | D26: 1 | E26: flag | F26: 1=áp dụng, 0=Head từ chối quý này. Q1/2026 Hoài từ chối | G26: head_bonus_apply
B28: 3. POOL KAE / BO
B29: STT | C29: Mô tả | D29: Giá trị | E29: Đơn vị | F29: Ghi chú / Công thức | G29: Named Range
B30: 1 | C30: Pool KAE - Admin | D30: 0.05 | E30: % | F30: 5% × profit paid KAE Admin | G30: pool_kae_admin
B31: 2 | C31: Pool KAE - Sale | D31: 0.02 | E31: % | F31: 2% × profit paid KAE Sale | G31: pool_kae_sale
B32: 3 | C32: Rate BO / Sale khác | D32: 0.08 | E32: % | F32: Flat 8% profit paid | G32: rate_bo
B34: 4. PHẠT CÔNG NỢ
B35: STT | C35: Mô tả | D35: Giá trị | E35: Đơn vị | F35: Ghi chú / Công thức | G35: Named Range
B36: 1 | C36: Rate phạt công nợ / tháng | D36: 0.01 | E36: % | F36: 1% × số_tháng × DT_sau_thuế | G36: phat_no_ratio
B37: 2 | C37: Giảm nợ khi chuyển admin | D37: 0.5 | E37: % | F37: Nợ 60+ chuyển admin | G37: phat_60plus_giam
B39: 5. THUẾ TNCN (theo file gốc)
B40: STT | C40: Mô tả | D40: Giá trị | E40: Đơn vị | F40: Ghi chú / Công thức | G40: Named Range
B41: 1 | C41: Giảm trừ bản thân / quý | D41: 33000000 | E41: VND | F41: 11tr × 3 tháng | G41: giam_tru_ca_nhan_quy
B42: 2 | C42: Giảm trừ phụ thuộc / quý | D42: 13200000 | E42: VND | F42: 4.4tr × 3 tháng | G42: giam_tru_phu_thuoc_quy
B44: Bậc thuế TNCN (theo file gốc - 5 bậc quý)
B45: Bậc | C45: Rate | D45: Giảm trừ (VND) | E45: Ghi chú
B46: 1 | C46: 0.05 | D46: 0 | E46: Bậc 1
B47: 2 | C47: 0.1 | D47: 500000 | E47: Bậc 2
...

Sheet Data
B2: DỮ LIỆU NGUỒN — Q1/2026
B4: A. JOBS | P4: B. PENALTY 60+ | X4: C. PENALTY UNPAID Q1 | AH4: D. TỔNG PHẠT / SALE | AN4: E. KH MỚI TRONG QUÝ (master)
B5: Thang | C5: Ma_Job | D5: Sale | E5: Khach_Hang | F5: Nhom_SP | G5: Product | H5: Team | I5: Doanh_Thu | J5: Chi_Phi | K5: Profit | L5: Paid_Status | M5: KH_Loai | N5: KAE | P5: Ma_KH | Q5: Ten_KH | R5: So_Tien | S5: Sale_Assign | T5: Chuyen_Admin | U5: So_Tien_Phat | V5: Note | X5: Thang | Y5: Ma_Job | Z5: DT_truoc_thue | AA5: DT_sau_thue | AB5: Sale | AC5: Khach_Hang | AD5: So_Thang | AE5: Phat | AH5: Ma_NV | AI5: Ho_Ten | AJ5: Phat_60plus | AK5: Phat_Unpaid | AL5: Tong_Phat | AN5: STT | AO5: Ten_SMS | AP5: Ten_Day_Du | AQ5: Ngay_HD_Dau | AR5: Ngay_Het_6t | AS5: Sale_Owner | AT5: Note | AU5: Tinh_KHmoi

Sheet Calc_Sale
B2: TÍNH INCENTIVE — SALE COM CHÍNH THỨC Q1/2026
B4: Ma_NV | C4: Ho_Ten | D4: Doanh_Thu | E4: Chi_Phi | F4: Profit_Total | G4: Profit_Paid | H4: Profit_Unpaid | I4: Target_Q | J4: Adj_Rate | K4: R_M1_Paid | L4: S_M2_Paid | M4: T_M3_Paid | N4: Rate_M1 | O4: Rate_M2 | P4: Rate_M3 | Q4: U_Muc1 | R4: V_Muc2 | S4: W_Muc3 | T4: X_Gross | U4: Z_BP | V4: AA_Phat | W4: AB_Incentive
B5: TTN22.005 | C5: Phạm Thị Thương Hoài | D5: =SUMIFS(tbl_jobs[Doanh_Thu],tbl_jobs[Sale],C5) -> 0 | E5: =SUMIFS(tbl_jobs[Chi_Phi],tbl_jobs[Sale],C5) -> 0 | F5: =SUMIFS(tbl_jobs[Profit],tbl_jobs[Sale],C5) -> 0 | G5: =SUMIFS(tbl_jobs[Profit],tbl_jobs[Sale],C5,tbl_jobs[Paid_Status],"Paid") -> 0 | H5: =F5-G5 -> 0 | I5: =VLOOKUP(C5,tbl_staff[[Ho_Ten]:[KHmoi_Adj_Rate]],9,0) -> #N/A | J5: =VLOOKUP(C5,tbl_staff[[Ho_Ten]:[KHmoi_Adj_Rate]],12,0) -> #N/A | K5: =SUMIFS(tbl_jobs[Profit],tbl_jobs[Sale],C5,tbl_jobs[KH_Loai],"Mức 1",tbl_jobs[Paid_Status],"Paid") -> 0 | L5: =SUMIFS(tbl_jobs[Profit],tbl_jobs[Sale],C5,tbl_jobs[KH_Loai],"Mức 2",tbl_jobs[Paid_Status],"Paid") -> 0 | M5: =SUMIFS(tbl_jobs[Profit],tbl_jobs[Sale],C5,tbl_jobs[KH_Loai],"Mức 3",tbl_jobs[Paid_Status],"Paid") -> 0 | N5: =rate_muc1 -> 0.08 | O5: =rate_muc2+J5 -> #N/A | P5: =rate_muc3+J5 -> #N/A | Q5: =IF(K5-I5>0,(K5-I5)*N5,0) -> #N/A | R5: =IF(Q5>0,L5*O5,IF(L5-(I5-K5)>0,(L5-(I5-K5))*O5,0)) -> #N/A | S5: =IF(R5>0,M5*P5,IF(M5-I5>0,(M5-I5)*P5,0)) -> #N/A | T5: =Q5+R5+S5 -> #N/A | U5: =IF(B5=head_ma_nv,$E$18,0) -> 0 | V5: =-IFERROR(VLOOKUP(B5,tbl_penalty_sum[[Ma_NV]:[Tong_Phat]],5,0),0) -> 0 | W5: =IF(T5+U5+V5<incentive_floor,incentive_floor,T5+U5+V5) -> #N/A
B6: TTN24.002 | C6: Phạm Trần Hiếu | D6: =SUMIFS(tbl_jobs[Doanh_Thu],tbl_jobs[Sale],C6) -> 0 | E6: =SUMIFS(tbl_jobs[Chi_Phi],tbl_jobs[Sale],C6) -> 0 | F6: =SUMIFS(tbl_jobs[Profit],tbl_jobs[Sale],C6) -> 0 | G6: =SUMIFS(tbl_jobs[Profit],tbl_jobs[Sale],C6,tbl_jobs[Paid_Status],"Paid") -> 0 | H6: =F6-G6 -> 0 | I6: =VLOOKUP(C6,tbl_staff[[Ho_Ten]:[KHmoi_Adj_Rate]],9,0) -> #N/A | J6: =VLOOKUP(C6,tbl_staff[[Ho_Ten]:[KHmoi_Adj_Rate]],12,0) -> #N/A | K6: =SUMIFS(tbl_jobs[Profit],tbl_jobs[Sale],C6,tbl_jobs[KH_Loai],"Mức 1",tbl_jobs[Paid_Status],"Paid") -> 0 | L6: =SUMIFS(tbl_jobs[Profit],tbl_jobs[Sale],C6,tbl_jobs[KH_Loai],"Mức 2",tbl_jobs[Paid_Status],"Paid") -> 0 | M6: =SUMIFS(tbl_jobs[Profit],tbl_jobs[Sale],C6,tbl_jobs[KH_Loai],"Mức 3",tbl_jobs[Paid_Status],"Paid") -> 0 | N6: =rate_muc1 -> 0.08 | O6: =rate_muc2+J6 -> #N/A | P6: =rate_muc3+J6 -> #N/A | Q6: =IF(K6-I6>0,(K6-I6)*N6,0) -> #N/A | R6: =IF(Q6>0,L6*O6,IF(L6-(I6-K6)>0,(L6-(I6-K6))*O6,0)) -> #N/A | S6: =IF(R6>0,M6*P6,IF(M6-I6>0,(M6-I6)*P6,0)) -> #N/A | T6: =Q6+R6+S6 -> #N/A | U6: =IF(B6=head_ma_nv,$E$18,0) -> 0 | V6: =-IFERROR(VLOOKUP(B6,tbl_penalty_sum[[Ma_NV]:[Tong_Phat]],5,0),0) -> 0 | W6: =IF(T6+U6+V6<incentive_floor,incentive_floor,T6+U6+V6) -> #N/A
B7: TTN24.006 | C7: Trần Văn Hiếu | D7: =SUMIFS(tbl_jobs[Doanh_Thu],tbl_jobs[Sale],C7) -> 0 | E7: =SUMIFS(tbl_jobs[Chi_Phi],tbl_jobs[Sale],C7) -> 0 | F7: =SUMIFS(tbl_jobs[Profit],tbl_jobs[Sale],C7) -> 0 | G7: =SUMIFS(tbl_jobs[Profit],tbl_jobs[Sale],C7,tbl_jobs[Paid_Status],"Paid") -> 0 | H7: =F7-G7 -> 0 | I7: =VLOOKUP(C7,tbl_staff[[Ho_Ten]:[KHmoi_Adj_Rate]],9,0) -> #N/A | J7: =VLOOKUP(C7,tbl_staff[[Ho_Ten]:[KHmoi_Adj_Rate]],12,0) -> #N/A | K7: =SUMIFS(tbl_jobs[Profit],tbl_jobs[Sale],C7,tbl_jobs[KH_Loai],"Mức 1",tbl_jobs[Paid_Status],"Paid") -> 0 | L7: =SUMIFS(tbl_jobs[Profit],tbl_jobs[Sale],C7,tbl_jobs[KH_Loai],"Mức 2",tbl_jobs[Paid_Status],"Paid") -> 0 | M7: =SUMIFS(tbl_jobs[Profit],tbl_jobs[Sale],C7,tbl_jobs[KH_Loai],"Mức 3",tbl_jobs[Paid_Status],"Paid") -> 0 | N7: =rate_muc1 -> 0.08 | O7: =rate_muc2+J7 -> #N/A | P7: =rate_muc3+J7 -> #N/A | Q7: =IF(K7-I7>0,(K7-I7)*N7,0) -> #N/A | R7: =IF(Q7>0,L7*O7,IF(L7-(I7-K7)>0,(L7-(I7-K7))*O7,0)) -> #N/A | S7: =IF(R7>0,M7*P7,IF(M7-I7>0,(M7-I7)*P7,0)) -> #N/A | T7: =Q7+R7+S7 -> #N/A | U7: =IF(B7=head_ma_nv,$E$18,0) -> 0 | V7: =-IFERROR(VLOOKUP(B7,tbl_penalty_sum[[Ma_NV]:[Tong_Phat]],5,0),0) -> 0 | W7: =IF(T7+U7+V7<incentive_floor,incentive_floor,T7+U7+V7) -> #N/A
B8: TTN25.001 | C8: Lê Thị Hằng | D8: =SUMIFS(tbl_jobs[Doanh_Thu],tbl_jobs[Sale],C8) -> 0 | E8: =SUMIFS(tbl_jobs[Chi_Phi],tbl_jobs[Sale],C8) -> 0 | F8: =SUMIFS(tbl_jobs[Profit],tbl_jobs[Sale],C8) -> 0 | G8: =SUMIFS(tbl_jobs[Profit],tbl_jobs[Sale],C8,tbl_jobs[Paid_Status],"Paid") -> 0 | H8: =F8-G8 -> 0 | I8: =VLOOKUP(C8,tbl_staff[[Ho_Ten]:[KHmoi_Adj_Rate]],9,0) -> #N/A | J8: =VLOOKUP(C8,tbl_staff[[Ho_Ten]:[KHmoi_Adj_Rate]],12,0) -> #N/A | K8: =SUMIFS(tbl_jobs[Profit],tbl_jobs[Sale],C8,tbl_jobs[KH_Loai],"Mức 1",tbl_jobs[Paid_Status],"Paid") -> 0 | L8: =SUMIFS(tbl_jobs[Profit],tbl_jobs[Sale],C8,tbl_jobs[KH_Loai],"Mức 2",tbl_jobs[Paid_Status],"Paid") -> 0 | M8: =SUMIFS(tbl_jobs[Profit],tbl_jobs[Sale],C8,tbl_jobs[KH_Loai],"Mức 3",tbl_jobs[Paid_Status],"Paid") -> 0 | N8: =rate_muc1 -> 0.08 | O8: =rate_muc2+J8 -> #N/A | P8: =rate_muc3+J8 -> #N/A | Q8: =IF(K8-I8>0,(K8-I8)*N8,0) -> #N/A | R8: =IF(Q8>0,L8*O8,IF(L8-(I8-K8)>0,(L8-(I8-K8))*O8,0)) -> #N/A | S8: =IF(R8>0,M8*P8,IF(M8-I8>0,(M8-I8)*P8,0)) -> #N/A | T8: =Q8+R8+S8 -> #N/A | U8: =IF(B8=head_ma_nv,$E$18,0) -> 0 | V8: =-IFERROR(VLOOKUP(B8,tbl_penalty_sum[[Ma_NV]:[Tong_Phat]],5,0),0) -> 0 | W8: =IF(T8+U8+V8<incentive_floor,incentive_floor,T8+U8+V8) -> #N/A
B9: TTN25.005 | C9: Kim Thanh Thư | D9: =SUMIFS(tbl_jobs[Doanh_Thu],tbl_jobs[Sale],C9) -> 0 | E9: =SUMIFS(tbl_jobs[Chi_Phi],tbl_jobs[Sale],C9) -> 0 | F9: =SUMIFS(tbl_jobs[Profit],tbl_jobs[Sale],C9) -> 0 | G9: =SUMIFS(tbl_jobs[Profit],tbl_jobs[Sale],C9,tbl_jobs[Paid_Status],"Paid") -> 0 | H9: =F9-G9 -> 0 | I9: =VLOOKUP(C9,tbl_staff[[Ho_Ten]:[KHmoi_Adj_Rate]],9,0) -> #N/A | J9: =VLOOKUP(C9,tbl_staff[[Ho_Ten]:[KHmoi_Adj_Rate]],12,0) -> #N/A | K9: =SUMIFS(tbl_jobs[Profit],tbl_jobs[Sale],C9,tbl_jobs[KH_Loai],"Mức 1",tbl_jobs[Paid_Status],"Paid") -> 0 | L9: =SUMIFS(tbl_jobs[Profit],tbl_jobs[Sale],C9,tbl_jobs[KH_Loai],"Mức 2",tbl_jobs[Paid_Status],"Paid") -> 0 | M9: =SUMIFS(tbl_jobs[Profit],tbl_jobs[Sale],C9,tbl_jobs[KH_Loai],"Mức 3",tbl_jobs[Paid_Status],"Paid") -> 0 | N9: =rate_muc1 -> 0.08 | O9: =rate_muc2+J9 -> #N/A | P9: =rate_muc3+J9 -> #N/A | Q9: =IF(K9-I9>0,(K9-I9)*N9,0) -> #N/A | R9: =IF(Q9>0,L9*O9,IF(L9-(I9-K9)>0,(L9-(I9-K9))*O9,0)) -> #N/A | S9: =IF(R9>0,M9*P9,IF(M9-I9>0,(M9-I9)*P9,0)) -> #N/A | T9: =Q9+R9+S9 -> #N/A | U9: =IF(B9=head_ma_nv,$E$18,0) -> 0 | V9: =-IFERROR(VLOOKUP(B9,tbl_penalty_sum[[Ma_NV]:[Tong_Phat]],5,0),0) -> 0 | W9: =IF(T9+U9+V9<incentive_floor,incentive_floor,T9+U9+V9) -> #N/A
B10: TTN25.010 | C10: Nguyễn Duy Tân | D10: =SUMIFS(tbl_jobs[Doanh_Thu],tbl_jobs[Sale],C10) -> 0 | E10: =SUMIFS(tbl_jobs[Chi_Phi],tbl_jobs[Sale],C10) -> 0 | F10: =SUMIFS(tbl_jobs[Profit],tbl_jobs[Sale],C10) -> 0 | G10: =SUMIFS(tbl_jobs[Profit],tbl_jobs[Sale],C10,tbl_jobs[Paid_Status],"Paid") -> 0 | H10: =F10-G10 -> 0 | I10: =VLOOKUP(C10,tbl_staff[[Ho_Ten]:[KHmoi_Adj_Rate]],9,0) -> #N/A | J10: =VLOOKUP(C10,tbl_staff[[Ho_Ten]:[KHmoi_Adj_Rate]],12,0) -> #N/A | K10: =SUMIFS(tbl_jobs[Profit],tbl_jobs[Sale],C10,tbl_jobs[KH_Loai],"Mức 1",tbl_jobs[Paid_Status],"Paid") -> 0 | L10: =SUMIFS(tbl_jobs[Profit],tbl_jobs[Sale],C10,tbl_jobs[KH_Loai],"Mức 2",tbl_jobs[Paid_Status],"Paid") -> 0 | M10: =SUMIFS(tbl_jobs[Profit],tbl_jobs[Sale],C10,tbl_jobs[KH_Loai],"Mức 3",tbl_jobs[Paid_Status],"Paid") -> 0 | N10: =rate_muc1 -> 0.08 | O10: =rate_muc2+J10 -> #N/A | P10: =rate_muc3+J10 -> #N/A | Q10: =IF(K10-I10>0,(K10-I10)*N10,0) -> #N/A | R10: =IF(Q10>0,L10*O10,IF(L10-(I10-K10)>0,(L10-(I10-K10))*O10,0)) -> #N/A | S10: =IF(R10>0,M10*P10,IF(M10-I10>0,(M10-I10)*P10,0)) -> #N/A | T10: =Q10+R10+S10 -> #N/A | U10: =IF(B10=head_ma_nv,$E$18,0) -> 0 | V10: =-IFERROR(VLOOKUP(B10,tbl_penalty_sum[[Ma_NV]:[Tong_Phat]],5,0),0) -> 0 | W10: =IF(T10+U10+V10<incentive_floor,incentive_floor,T10+U10+V10) -> #N/A
B11: TTN25.007 | C11: Nguyễn Gia Bảo | D11: =SUMIFS(tbl_jobs[Doanh_Thu],tbl_jobs[Sale],C11) -> 0 | E11: =SUMIFS(tbl_jobs[Chi_Phi],tbl_jobs[Sale],C11) -> 0 | F11: =SUMIFS(tbl_jobs[Profit],tbl_jobs[Sale],C11) -> 0 | G11: =SUMIFS(tbl_jobs[Profit],tbl_jobs[Sale],C11,tbl_jobs[Paid_Status],"Paid") -> 0 | H11: =F11-G11 -> 0 | I11: =VLOOKUP(C11,tbl_staff[[Ho_Ten]:[KHmoi_Adj_Rate]],9,0) -> #N/A | J11: =VLOOKUP(C11,tbl_staff[[Ho_Ten]:[KHmoi_Adj_Rate]],12,0) -> #N/A | K11: =SUMIFS(tbl_jobs[Profit],tbl_jobs[Sale],C11,tbl_jobs[KH_Loai],"Mức 1",tbl_jobs[Paid_Status],"Paid") -> 0 | L11: =SUMIFS(tbl_jobs[Profit],tbl_jobs[Sale],C11,tbl_jobs[KH_Loai],"Mức 2",tbl_jobs[Paid_Status],"Paid") -> 0 | M11: =SUMIFS(tbl_jobs[Profit],tbl_jobs[Sale],C11,tbl_jobs[KH_Loai],"Mức 3",tbl_jobs[Paid_Status],"Paid") -> 0 | N11: =rate_muc1 -> 0.08 | O11: =rate_muc2+J11 -> #N/A | P11: =rate_muc3+J11 -> #N/A | Q11: =IF(K11-I11>0,(K11-I11)*N11,0) -> #N/A | R11: =IF(Q11>0,L11*O11,IF(L11-(I11-K11)>0,(L11-(I11-K11))*O11,0)) -> #N/A | S11: =IF(R11>0,M11*P11,IF(M11-I11>0,(M11-I11)*P11,0)) -> #N/A | T11: =Q11+R11+S11 -> #N/A | U11: =IF(B11=head_ma_nv,$E$18,0) -> 0 | V11: =-IFERROR(VLOOKUP(B11,tbl_penalty_sum[[Ma_NV]:[Tong_Phat]],5,0),0) -> 0 | W11: =IF(T11+U11+V11<incentive_floor,incentive_floor,T11+U11+V11) -> #N/A
B13: HEAD BONUS — Thưởng Trưởng BP KD (loại Head khỏi SUM)
B14: Metric | C14: Công thức | E14: Sum_Profit_BP | F14: Sum_Target_BP | G14: Sum_Vuot | H14: Sum_KHmoi_Giao | I14: Sum_KHmoi_Dat
B15: SUM toàn BP (trừ Head) | E15: =SUMIFS(G5:G11,B5:B11,"<>"&head_ma_nv,I5:I11,">0") -> 0 | F15: =SUMIFS(I5:I11,B5:B11,"<>"&head_ma_nv,I5:I11,">0") -> 0 | G15: =E15-F15 -> 0 | H15: =SUMIFS(tbl_staff[KHmoi_Giao],tbl_staff[Team],"COM") -> 18 | I15: =SUMIFS(tbl_staff[KHmoi_Dat],tbl_staff[Team],"COM") -> 0
B16: DeltaKH toàn BP | E16: =I15-H15 -> -18
B17: Base / Adj bonus | C17: Base=rate_bpsale×Vuot; Adj asymmetric: ΔKH>=0 dùng step_cong, ΔKH<0 dùng step_tru | E17: =rate_bpsale*MAX(0,G15) -> 0 | F17: =IF(E16>=0,MIN(bpsale_cap_cong,E16*bpsale_step_cong),MAX(-bpsale_cap_tru,E16*bpsale_step_tru))*MAX(0,G15) -> 0
B18: TỔNG HEAD BONUS | C18: (Base + Adj) × head_bonus_apply — 0 nếu Head từ chối | E18: =(E17+F17)*head_bonus_apply -> 0

Sheet Calc_KAE
B2: TÍNH INCENTIVE — TEAM KAE Q1/2026
B4: 1. POOL THÁNG
B5: Nguon | C5: T1_Profit | D5: T2_Profit | E5: T3_Profit | F5: Rate | G5: T1_Pool | H5: T2_Pool | I5: T3_Pool
B6: KAE Admin | C6: =SUMIFS(tbl_jobs[Profit],tbl_jobs[KAE],"KAE Admin",tbl_jobs[Thang],1) -> 0 | D6: =SUMIFS(tbl_jobs[Profit],tbl_jobs[KAE],"KAE Admin",tbl_jobs[Thang],2) -> 0 | E6: =SUMIFS(tbl_jobs[Profit],tbl_jobs[KAE],"KAE Admin",tbl_jobs[Thang],3) -> 0 | F6: =pool_kae_admin -> 0.05 | G6: =C6*F6 -> 0 | H6: =D6*F6 -> 0 | I6: =E6*F6 -> 0
B7: KAE Sale | C7: =SUMIFS(tbl_jobs[Profit],tbl_jobs[KAE],"KAE Sale",tbl_jobs[Thang],1) -> 0 | D7: =SUMIFS(tbl_jobs[Profit],tbl_jobs[KAE],"KAE Sale",tbl_jobs[Thang],2) -> 0 | E7: =SUMIFS(tbl_jobs[Profit],tbl_jobs[KAE],"KAE Sale",tbl_jobs[Thang],3) -> 0 | F7: =pool_kae_sale -> 0.02 | G7: =C7*F7 -> 0 | H7: =D7*F7 -> 0 | I7: =E7*F7 -> 0
B8: TỔNG POOL | G8: =G6+G7 -> 0 | H8: =H6+H7 -> 0 | I8: =I6+I7 -> 0
B11: 2. SỐ KAE HOẠT ĐỘNG / THÁNG
B12: Thang | C12: So_KAE
B13: 1
B14: 2
B15: 3
B18: 3. INCENTIVE / TỪNG KAE (T*_Ratio: 1=full, 0=vắng, 0.5=nửa)
B19: Ma_NV | C19: Ho_Ten | D19: T1_Ratio | E19: T2_Ratio | F19: T3_Ratio | G19: T1_Share | H19: T2_Share | I19: T3_Share | J19: Tong_Chia | K19: Tru | L19: Phat | M19: Incentive
G20: =$G$8/$C$13*D20 -> #DIV/0! | H20: =$H$8/$C$14*E20 -> #DIV/0! | I20: =$I$8/$C$15*F20 -> #DIV/0! | J20: =G20+H20+I20 -> #DIV/0! | M20: =J20-K20-L20 -> #DIV/0!
G21: =$G$8/$C$13*D21 -> #DIV/0! | H21: =$H$8/$C$14*E21 -> #DIV/0! | I21: =$I$8/$C$15*F21 -> #DIV/0! | J21: =G21+H21+I21 -> #DIV/0! | M21: =J21-K21-L21 -> #DIV/0!
G22: =$G$8/$C$13*D22 -> #DIV/0! | H22: =$H$8/$C$14*E22 -> #DIV/0! | I22: =$I$8/$C$15*F22 -> #DIV/0! | J22: =G22+H22+I22 -> #DIV/0! | M22: =J22-K22-L22 -> #DIV/0!
G23: =$G$8/$C$13*D23 -> #DIV/0! | H23: =$H$8/$C$14*E23 -> #DIV/0! | I23: =$I$8/$C$15*F23 -> #DIV/0! | J23: =G23+H23+I23 -> #DIV/0! | M23: =J23-K23-L23 -> #DIV/0!
G24: =$G$8/$C$13*D24 -> #DIV/0! | H24: =$H$8/$C$14*E24 -> #DIV/0! | I24: =$I$8/$C$15*F24 -> #DIV/0! | J24: =G24+H24+I24 -> #DIV/0! | M24: =J24-K24-L24 -> #DIV/0!
G25: =$G$8/$C$13*D25 -> #DIV/0! | H25: =$H$8/$C$14*E25 -> #DIV/0! | I25: =$I$8/$C$15*F25 -> #DIV/0! | J25: =G25+H25+I25 -> #DIV/0! | M25: =J25-K25-L25 -> #DIV/0!

Sheet Calc_Other
B2: TÍNH INCENTIVE — SALE KHÁC / BO Q1/2026
B4: Ma_NV | C4: Ho_Ten | D4: Doanh_Thu | E4: Chi_Phi | F4: Profit_Total | G4: Profit_Paid | H4: Rate | I4: Incentive
D5: =SUMIFS(tbl_jobs[Doanh_Thu],tbl_jobs[Sale],C5) -> 0 | E5: =SUMIFS(tbl_jobs[Chi_Phi],tbl_jobs[Sale],C5) -> 0 | F5: =SUMIFS(tbl_jobs[Profit],tbl_jobs[Sale],C5) -> 0 | G5: =SUMIFS(tbl_jobs[Profit],tbl_jobs[Sale],C5,tbl_jobs[Paid_Status],"Paid") -> 0 | H5: =rate_bo -> 0.08 | I5: =ROUND(G5*H5,0) -> 0
D6: =SUMIFS(tbl_jobs[Doanh_Thu],tbl_jobs[Sale],C6) -> 0 | E6: =SUMIFS(tbl_jobs[Chi_Phi],tbl_jobs[Sale],C6) -> 0 | F6: =SUMIFS(tbl_jobs[Profit],tbl_jobs[Sale],C6) -> 0 | G6: =SUMIFS(tbl_jobs[Profit],tbl_jobs[Sale],C6,tbl_jobs[Paid_Status],"Paid") -> 0 | H6: =rate_bo -> 0.08 | I6: =ROUND(G6*H6,0) -> 0
D7: =SUMIFS(tbl_jobs[Doanh_Thu],tbl_jobs[Sale],C7) -> 0 | E7: =SUMIFS(tbl_jobs[Chi_Phi],tbl_jobs[Sale],C7) -> 0 | F7: =SUMIFS(tbl_jobs[Profit],tbl_jobs[Sale],C7) -> 0 | G7: =SUMIFS(tbl_jobs[Profit],tbl_jobs[Sale],C7,tbl_jobs[Paid_Status],"Paid") -> 0 | H7: =rate_bo -> 0.08 | I7: =ROUND(G7*H7,0) -> 0

Sheet Payout
B2: BẢNG CHI INCENTIVE + THUẾ TNCN — Q1/2026
B4: STT | C4: Ma_NV | D4: Ho_Ten | E4: Incentive_Gross | F4: TN_Luong_Chiu_Thue | G4: Phi_OPS | H4: BHXH | I4: Giam_Tru | J4: TN_Chiu_Thue | K4: Thue_TNCN | L4: Thue_Da_Tru_Luong | M4: Thue_Da_Tru_OPS | N4: Thue_Phai_Nop | O4: Cong_Tru_Khac | P4: Incentive_Thuc_Nhan
B5: 1 | E5: =IFERROR(VLOOKUP(D5,Calc_Sale!$C$5:$W$11,21,0),0) -> 0 | F5: 0 | G5: 0 | H5: 0 | I5: 0 | J5: =MAX(0,E5+F5+G5-H5-I5) -> 0 | K5: =ROUND(IF(I5>0,MAX(J5*{5,10,20,30,35}%-{0,500000,3500000,9500000,14500000},0),J5*10%),0) -> 0 | L5: 0 | M5: 0 | N5: =K5-L5-M5 -> 0 | O5: 0 | P5: =ROUND(E5-N5+O5,0) -> 0
B6: 2 | E6: =IFERROR(VLOOKUP(D6,Calc_Sale!$C$5:$W$11,21,0),0) -> 0 | F6: 0 | G6: 0 | H6: 0 | I6: 0 | J6: =MAX(0,E6+F6+G6-H6-I6) -> 0 | K6: =ROUND(IF(I6>0,MAX(J6*{5,10,20,30,35}%-{0,500000,3500000,9500000,14500000},0),J6*10%),0) -> 0 | L6: 0 | M6: 0 | N6: =K6-L6-M6 -> 0 | O6: 0 | P6: =ROUND(E6-N6+O6,0) -> 0
B7: 3 | E7: =IFERROR(VLOOKUP(D7,Calc_Sale!$C$5:$W$11,21,0),0) -> 0 | F7: 0 | G7: 0 | H7: 0 | I7: 0 | J7: =MAX(0,E7+F7+G7-H7-I7) -> 0 | K7: =ROUND(IF(I7>0,MAX(J7*{5,10,20,30,35}%-{0,500000,3500000,9500000,14500000},0),J7*10%),0) -> 0 | L7: 0 | M7: 0 | N7: =K7-L7-M7 -> 0 | O7: 0 | P7: =ROUND(E7-N7+O7,0) -> 0
B8: 4 | E8: =IFERROR(VLOOKUP(D8,Calc_Sale!$C$5:$W$11,21,0),0) -> 0 | F8: 0 | G8: 0 | H8: 0 | I8: 0 | J8: =MAX(0,E8+F8+G8-H8-I8) -> 0 | K8: =ROUND(IF(I8>0,MAX(J8*{5,10,20,30,35}%-{0,500000,3500000,9500000,14500000},0),J8*10%),0) -> 0 | L8: 0 | M8: 0 | N8: =K8-L8-M8 -> 0 | O8: 0 | P8: =ROUND(E8-N8+O8,0) -> 0
B9: 5 | E9: =IFERROR(VLOOKUP(D9,Calc_Sale!$C$5:$W$11,21,0),0) -> 0 | F9: 0 | G9: 0 | H9: 0 | I9: 0 | J9: =MAX(0,E9+F9+G9-H9-I9) -> 0 | K9: =ROUND(IF(I9>0,MAX(J9*{5,10,20,30,35}%-{0,500000,3500000,9500000,14500000},0),J9*10%),0) -> 0 | L9: 0 | M9: 0 | N9: =K9-L9-M9 -> 0 | O9: 0 | P9: =ROUND(E9-N9+O9,0) -> 0
B10: 6 | E10: =IFERROR(VLOOKUP(D10,Calc_Sale!$C$5:$W$11,21,0),0) -> 0 | F10: 0 | G10: 0 | H10: 0 | I10: 0 | J10: =MAX(0,E10+F10+G10-H10-I10) -> 0 | K10: =ROUND(IF(I10>0,MAX(J10*{5,10,20,30,35}%-{0,500000,3500000,9500000,14500000},0),J10*10%),0) -> 0 | L10: 0 | M10: 0 | N10: =K10-L10-M10 -> 0 | O10: 0 | P10: =ROUND(E10-N10+O10,0) -> 0
B11: 7 | E11: =IFERROR(VLOOKUP(D11,Calc_Sale!$C$5:$W$11,21,0),0) -> 0 | F11: 0 | G11: 0 | H11: 0 | I11: 0 | J11: =MAX(0,E11+F11+G11-H11-I11) -> 0 | K11: =ROUND(IF(I11>0,MAX(J11*{5,10,20,30,35}%-{0,500000,3500000,9500000,14500000},0),J11*10%),0) -> 0 | L11: 0 | M11: 0 | N11: =K11-L11-M11 -> 0 | O11: 0 | P11: =ROUND(E11-N11+O11,0) -> 0
B12: 8 | E12: =IFERROR(VLOOKUP(D12,Calc_KAE!$C$1:$M$100,11,0),0) -> 0 | F12: 0 | G12: 0 | H12: 0 | I12: 0 | J12: =MAX(0,E12+F12+G12-H12-I12) -> 0 | K12: =ROUND(IF(I12>0,MAX(J12*{5,10,20,30,35}%-{0,500000,3500000,9500000,14500000},0),J12*10%),0) -> 0 | L12: 0 | M12: 0 | N12: =K12-L12-M12 -> 0 | O12: 0 | P12: =ROUND(E12-N12+O12,0) -> 0
B13: 9 | E13: =IFERROR(VLOOKUP(D13,Calc_KAE!$C$1:$M$100,11,0),0)+IFERROR(VLOOKUP(D13,Calc_Other!$C$5:$I$20,7,0),0) -> 0 | F13: 0 | G13: 0 | H13: 0 | I13: 0 | J13: =MAX(0,E13+F13+G13-H13-I13) -> 0 | K13: =ROUND(IF(I13>0,MAX(J13*{5,10,20,30,35}%-{0,500000,3500000,9500000,14500000},0),J13*10%),0) -> 0 | L13: 0 | M13: 0 | N13: =K13-L13-M13 -> 0 | O13: 0 | P13: =ROUND(E13-N13+O13,0) -> 0
B14: 10 | E14: =IFERROR(VLOOKUP(D14,Calc_KAE!$C$1:$M$100,11,0),0) -> 0 | F14: 0 | G14: 0 | H14: 0 | I14: 0 | J14: =MAX(0,E14+F14+G14-H14-I14) -> 0 | K14: =ROUND(IF(I14>0,MAX(J14*{5,10,20,30,35}%-{0,500000,3500000,9500000,14500000},0),J14*10%),0) -> 0 | L14: 0 | M14: 0 | N14: =K14-L14-M14 -> 0 | O14: 0 | P14: =ROUND(E14-N14+O14,0) -> 0
B15: 11 | E15: =IFERROR(VLOOKUP(D15,Calc_KAE!$C$1:$M$100,11,0),0) -> 0 | F15: 0 | G15: 0 | H15: 0 | I15: 0 | J15: =MAX(0,E15+F15+G15-H15-I15) -> 0 | K15: =ROUND(IF(I15>0,MAX(J15*{5,10,20,30,35}%-{0,500000,3500000,9500000,14500000},0),J15*10%),0) -> 0 | L15: 0 | M15: 0 | N15: =K15-L15-M15 -> 0 | O15: 0 | P15: =ROUND(E15-N15+O15,0) -> 0
B16: 12 | E16: =IFERROR(VLOOKUP(D16,Calc_KAE!$C$1:$M$100,11,0),0) -> 0 | F16: 0 | G16: 0 | H16: 0 | I16: 0 | J16: =MAX(0,E16+F16+G16-H16-I16) -> 0 | K16: =ROUND(IF(I16>0,MAX(J16*{5,10,20,30,35}%-{0,500000,3500000,9500000,14500000},0),J16*10%),0) -> 0 | L16: 0 | M16: 0 | N16: =K16-L16-M16 -> 0 | O16: 0 | P16: =ROUND(E16-N16+O16,0) -> 0
B17: 13 | E17: =IFERROR(VLOOKUP(D17,Calc_KAE!$C$1:$M$100,11,0),0) -> 0 | F17: 0 | G17: 0 | H17: 0 | I17: 0 | J17: =MAX(0,E17+F17+G17-H17-I17) -> 0 | K17: =ROUND(IF(I17>0,MAX(J17*{5,10,20,30,35}%-{0,500000,3500000,9500000,14500000},0),J17*10%),0) -> 0 | L17: 0 | M17: 0 | N17: =K17-L17-M17 -> 0 | O17: 0 | P17: =ROUND(E17-N17+O17,0) -> 0
B18: 14 | E18: =IFERROR(VLOOKUP(D18,Calc_Other!$C$5:$I$20,7,0),0) -> 0 | F18: 0 | G18: 0 | H18: 0 | I18: 0 | J18: =MAX(0,E18+F18+G18-H18-I18) -> 0 | K18: =ROUND(IF(I18>0,MAX(J18*{5,10,20,30,35}%-{0,500000,3500000,9500000,14500000},0),J18*10%),0) -> 0 | L18: 0 | M18: 0 | N18: =K18-L18-M18 -> 0 | O18: 0 | P18: =ROUND(E18-N18+O18,0) -> 0
B19: 15 | E19: =IFERROR(VLOOKUP(D19,Calc_Other!$C$5:$I$20,7,0),0) -> 0 | F19: 0 | G19: 0 | H19: 0 | I19: 0 | J19: =MAX(0,E19+F19+G19-H19-I19) -> 0 | K19: =ROUND(IF(I19>0,MAX(J19*{5,10,20,30,35}%-{0,500000,3500000,9500000,14500000},0),J19*10%),0) -> 0 | L19: 0 | M19: 0 | N19: =K19-L19-M19 -> 0 | O19: 0 | P19: =ROUND(E19-N19+O19,0) -> 0
D20: TOTAL | E20: =SUBTOTAL(9,E5:E19) -> 0 | J20: =SUBTOTAL(9,J5:J19) -> 0 | K20: =SUBTOTAL(9,K5:K19) -> 0 | N20: =SUBTOTAL(9,N5:N19) -> 0 | P20: =SUBTOTAL(9,P5:P19) -> 0
