Workbook
Name ky_ten: Assumption!$D$6
Name ky_bat_dau: Assumption!$D$7
Name ky_ket_thuc: Assumption!$D$8
Name loai_bang: Assumption!$D$9
Name gio_dem_bat_dau: Assumption!$D$13
Name gio_dem_ket_thuc: Assumption!$D$14
Name gio_loi_bat_dau: Assumption!$D$15
Name gio_loi_ket_thuc: Assumption!$D$16
Name moc_chia_ngay: Assumption!$D$17
Name moc_dem_tu: Assumption!$D$21
Name moc_loi_tu: Assumption!$D$22
Name moc_loi_den: Assumption!$D$23
Name moc_dem_den: Assumption!$D$24
Name kiem_tra_khung: Assumption!$D$25
Name rate_gio_bien: Assumption!$D$29
Name rate_gio_loi: Assumption!$D$30
Name he_so_le: Assumption!$D$31
Name bca_spark: Assumption!$D$35
Name bca_blaze: Assumption!$D$36
Name ops_0600_0800: Assumption!$D$40
Name ops_0800_1800: Assumption!$D$41
Name ops_1800_2200: Assumption!$D$42
Name ops_2200_0100: Assumption!$D$43
Name ops_0100_0600: Assumption!$D$44
Name ops_phu_troi_le: Assumption!$D$45
Name ops_kg_1nguoi: Assumption!$D$49
Name ops_nguoi_toi_da: Assumption!$D$50
Name giam_tru_ca_nhan_thang: Assumption!$D$54
Name giam_tru_phu_thuoc_thang: Assumption!$D$55
Name rate_khau_tru_vang_lai: Assumption!$D$56
Name thue_rate_1: Assumption!$C$60
Name thue_giam_1: Assumption!$D$60
Name thue_rate_2: Assumption!$C$61
Name thue_giam_2: Assumption!$D$61
Name thue_rate_3: Assumption!$C$62
Name thue_giam_3: Assumption!$D$62
Name thue_rate_4: Assumption!$C$63
Name thue_giam_4: Assumption!$D$63
Name thue_rate_5: Assumption!$C$64
Name thue_giam_5: Assumption!$D$64

Sheet Assumption
B2: BẢNG THAM SỐ PHỤ CẤP TRỰC ĐÊM + OPS — Tháng 08/2026
B3: Ô nền VÀNG là nhập tay. Ô nền XÁM là tự tính, đừng gõ đè. Mọi giờ nhập theo hệ 24 giờ (22:30, 06:30) — không dùng AM/PM.
B4: 1. KỲ TÍNH
B5: STT | C5: Mô tả | D5: Giá trị | E5: Đơn vị | F5: Ghi chú / Công thức | G5: Named Range
B6: 1 | C6: Kỳ tính (tên) | D6: Tháng 08/2026 | E6: text | F6: Nhãn kỳ báo cáo — công cụ HTML đọc ô này | G6: ky_ten
B7: 2 | C7: Ngày bắt đầu | D7: 46235 | E7: date | G7: ky_bat_dau
B8: 3 | C8: Ngày kết thúc | D8: 46265 | E8: date | G8: ky_ket_thuc
B9: 4 | C9: Loại bảng | D9: PHU_CAP | E9: text | F9: Cờ nhận diện cho công cụ HTML. Không sửa | G9: loai_bang
B11: 2. KHUNG GIỜ TRỰC ĐÊM — nhập hệ 24 giờ, không dùng AM/PM
B12: STT | C12: Mô tả | D12: Giá trị | E12: Đơn vị | F12: Ghi chú / Công thức | G12: Named Range
B13: 1 | C13: Khung ĐÊM bắt đầu | D13: 0.91666667 | E13: giờ | F13: Đổi ô này là đổi chính sách. Mọi công thức tự bám theo, KHÔNG phải sửa gì thêm | G13: gio_dem_bat_dau
B14: 2 | C14: Khung ĐÊM kết thúc (rạng sáng hôm sau) | D14: 0.25 | E14: giờ | F14: Ví dụ muốn trả tới 06:30 thì gõ 06:30 vào đây là xong | G14: gio_dem_ket_thuc
B15: 3 | C15: Khung LÕI bắt đầu (đơn giá cao) | D15: 0 | E15: giờ | F15: Phải nằm trong khung đêm. Phần còn lại của khung đêm là khung BIÊN | G15: gio_loi_bat_dau
B16: 4 | C16: Khung LÕI kết thúc | D16: 0.16666667 | E16: giờ | G16: gio_loi_ket_thuc
B17: 5 | C17: Mốc chia ngày | D17: 12 | E17: giờ | F17: Giờ nhỏ hơn mốc này được hiểu là rạng sáng HÔM SAU. Để 12 là hợp lý cho mọi ca đêm | G17: moc_chia_ngay
B19: 3. MỐC QUY ĐỔI — tự tính từ mục 2, KHÔNG sửa tay
B20: STT | C20: Mô tả | D20: Giá trị | E20: Đơn vị | F20: Ghi chú / Công thức | G20: Named Range
B21: 1 | C21: Trục: khung đêm bắt đầu | D21: =(HOUR(gio_dem_bat_dau)+MINUTE(gio_dem_bat_dau)/60)+IF((HOUR(gio_dem_bat_dau)+MINUTE(gio_dem_bat_dau)/60)<moc_chia_ngay,24,0) -> 22 | E21: giờ | G21: moc_dem_tu
B22: 2 | C22: Trục: khung lõi bắt đầu | D22: =(HOUR(gio_loi_bat_dau)+MINUTE(gio_loi_bat_dau)/60)+IF((HOUR(gio_loi_bat_dau)+MINUTE(gio_loi_bat_dau)/60)<moc_chia_ngay,24,0) -> 24 | E22: giờ | G22: moc_loi_tu
B23: 3 | C23: Trục: khung lõi kết thúc | D23: =(HOUR(gio_loi_ket_thuc)+MINUTE(gio_loi_ket_thuc)/60)+IF((HOUR(gio_loi_ket_thuc)+MINUTE(gio_loi_ket_thuc)/60)<moc_chia_ngay,24,0) -> 28 | E23: giờ | G23: moc_loi_den
B24: 4 | C24: Trục: khung đêm kết thúc | D24: =(HOUR(gio_dem_ket_thuc)+MINUTE(gio_dem_ket_thuc)/60)+IF((HOUR(gio_dem_ket_thuc)+MINUTE(gio_dem_ket_thuc)/60)<moc_chia_ngay,24,0) -> 30 | E24: giờ | G24: moc_dem_den
B25: 5 | C25: Kiểm tra khung giờ | D25: =IF(AND(moc_dem_tu<moc_loi_tu,moc_loi_tu<moc_loi_den,moc_loi_den<moc_dem_den),"Hợp lệ","LỖI: khung LÕI phải nằm gọn trong khung ĐÊM") -> Hợp lệ | F25: Phải hiện "Hợp lệ". Nếu báo LỖI thì xem lại 4 ô giờ ở mục 2 | G25: kiem_tra_khung
B27: 4. ĐƠN GIÁ PHỤ CẤP TRỰC ĐÊM
B28: STT | C28: Mô tả | D28: Giá trị | E28: Đơn vị | F28: Ghi chú / Công thức | G28: Named Range
B29: 1 | C29: Đơn giá khung BIÊN | D29: 30000 | E29: VND/giờ | F29: Phần khung đêm nằm ngoài khung lõi. Nguồn: phụ cấp trực đêm.docx mục 1 | G29: rate_gio_bien
B30: 2 | C30: Đơn giá khung LÕI | D30: 50000 | E30: VND/giờ | F30: Nguồn: phụ cấp trực đêm.docx mục 1 | G30: rate_gio_loi
B31: 3 | C31: Hệ số ngày lễ, Tết | D31: 1.5 | E31: lần | F31: Ngày lễ = (Phụ cấp giờ × 1,5) + (BCA × 1,5). Áp cho CẢ hai khung giờ | G31: he_so_le
B33: 5. THƯỞNG BCA THEO MỨC ĐỘ KHÓ
B34: STT | C34: Mô tả | D34: Giá trị | E34: Đơn vị | F34: Ghi chú / Công thức | G34: Named Range
B35: 1 | C35: BCA Spark (Mức 1) — ngày thường | D35: 100000 | E35: VND/ca | F35: Ca chỉ chạm khung biên 22–24 & 04–06. Ngày lễ = × he_so_le | G35: bca_spark
B36: 2 | C36: BCA Blaze (Mức 2) — ngày thường | D36: 200000 | E36: VND/ca | F36: Ca chạm khung lõi 00–04. Mỗi ca chỉ hưởng MỘT mức, lấy mức cao nhất | G36: bca_blaze
B38: 6. PHỤ CẤP OPS (theo giờ có mặt tại sân bay / cảng / ga)
B39: STT | C39: Mô tả | D39: Giá trị | E39: Đơn vị | F39: Ghi chú / Công thức | G39: Named Range
B40: 1 | C40: Khung 06:00 – 08:00 | D40: 200000 | E40: VND/chuyến | F40: Nguồn: tính OPS và Overtime.docx mục 3 | G40: ops_0600_0800
B41: 2 | C41: Khung 08:00 – 18:00 | D41: 150000 | E41: VND/chuyến | G41: ops_0800_1800
B42: 3 | C42: Khung 18:00 – 22:00 | D42: 200000 | E42: VND/chuyến | G42: ops_1800_2200
B43: 4 | C43: Khung 22:00 – 01:00 | D43: 400000 | E43: VND/chuyến | G43: ops_2200_0100
B44: 5 | C44: Khung 01:00 – 06:00 | D44: 600000 | E44: VND/chuyến | G44: ops_0100_0600
B45: 6 | C45: Phụ trội ngày lễ, Tết | D45: 300000 | E45: VND/chuyến | F45: Cộng thẳng, KHÔNG nhân he_so_le | G45: ops_phu_troi_le
B47: 7. ĐỊNH BIÊN NHÂN SỰ THEO TRỌNG LƯỢNG LÔ HÀNG
...

Sheet Data
B2: NHẬT KÝ CA TRỰC ĐÊM & CHUYẾN OPS — Tháng 08/2026
B3: Mỗi dòng là MỘT ca. Loai_Ca = TRUC_DEM (trực từ xa) hoặc OPS (có mặt tại sân bay/cảng/ga xử lý lô OBC, PET, CFS). Cột vàng nhập tay, cột còn lại là công thức. · GIỜ NHẬP THEO HỆ 24 GIỜ: 22:30 · 02:30 · 06:30 — không dùng AM/PM. · Ca qua đêm cứ nhập bình thường, công thức tự hiểu giờ kết thúc là rạng sáng hôm sau.
B5: STT | C5: Ngay | D5: Ma_NV | E5: Ho_Ten | F5: Loai_Ca | G5: Loai_Ngay | H5: Gio_Bat_Dau | I5: Gio_Ket_Thuc | J5: Ma_Job | K5: Trong_Luong_Kg | L5: So_Nhan_Su | M5: Backup_Nhan_Ca | N5: Gio_BD_Chuan | O5: Gio_KT_Chuan | P5: Gio_Bien | Q5: Gio_Loi | R5: Tong_Gio | S5: Muc_BCA | T5: PC_Gio | U5: Thuong_BCA | V5: PC_TrucDem | W5: Phi_OPS | X5: Tong_Dong | Y5: NS_Chuan | Z5: Canh_Bao | AA5: Ghi_Chu
B6: =IF($D6="","",1) | E6: =IFERROR(VLOOKUP(D6,Assumption!$B$69:$C$80,2,0),"") | N6: =IF(OR($F6<>"TRUC_DEM",$H6=""),"",(HOUR($H6)+MINUTE($H6)/60)+IF((HOUR($H6)+MINUTE($H6)/60)<moc_chia_ngay,24,0)) | O6: =IF(OR($F6<>"TRUC_DEM",$I6=""),"",(HOUR($I6)+MINUTE($I6)/60)+IF((HOUR($I6)+MINUTE($I6)/60)<moc_chia_ngay,24,0)) | P6: =IF($N6="","",MAX(0,MIN($O6,moc_loi_tu)-MAX($N6,moc_dem_tu))+MAX(0,MIN($O6,moc_dem_den)-MAX($N6,moc_loi_den))) | Q6: =IF($N6="","",MAX(0,MIN($O6,moc_loi_den)-MAX($N6,moc_loi_tu))) | R6: =IF($N6="","",$P6+$Q6) | S6: =IF($N6="","",IF($Q6>0,"Blaze",IF($P6>0,"Spark",""))) | T6: =IF($N6="",0,($P6*rate_gio_bien+$Q6*rate_gio_loi)*IF($G6="Lễ",he_so_le,1)) -> 0 | U6: =IF($N6="",0,IF($S6="Blaze",bca_blaze,IF($S6="Spark",bca_spark,0))*IF($G6="Lễ",he_so_le,1)) -> 0 | V6: =ROUND($T6+$U6,0) -> 0 | W6: =IF(OR($F6<>"OPS",$H6=""),0,ROUND(IF(AND($H6>=TIME(6,0,0),$H6<TIME(8,0,0)),ops_0600_0800,IF(AND($H6>=TIME(8,0,0),$H6<TIME(18,0,0)),ops_0800_1800,IF(AND($H6>=TIME(18,0,0),$H6<TIME(22,0,0)),ops_1800_2200,IF(OR($H6>=TIME(22,0,0),$H6<TIME(1,0,0)),ops_2200_0100,IF(AND($H6>=TIME(1,0,0),$H6<TIME(6,0,0)),ops_0100_0600,0)))))+IF($G6="Lễ",ops_phu_troi_le,0),0)) -> 0 | X6: =$V6+$W6 -> 0 | Y6: =IF(OR($F6<>"OPS",$K6=""),"",IF($K6<=ops_kg_1nguoi,1,ops_nguoi_toi_da)) | Z6: =IF($D6="","",IF(AND($F6="TRUC_DEM",$R6=0),"Ca ngoài khung 22:00–06:00",IF(AND($F6="OPS",$L6<>"",$Y6<>"",$L6<$Y6),"Thiếu người so với định biên","")))
B7: =IF($D7="","",2) | E7: =IFERROR(VLOOKUP(D7,Assumption!$B$69:$C$80,2,0),"") | N7: =IF(OR($F7<>"TRUC_DEM",$H7=""),"",(HOUR($H7)+MINUTE($H7)/60)+IF((HOUR($H7)+MINUTE($H7)/60)<moc_chia_ngay,24,0)) | O7: =IF(OR($F7<>"TRUC_DEM",$I7=""),"",(HOUR($I7)+MINUTE($I7)/60)+IF((HOUR($I7)+MINUTE($I7)/60)<moc_chia_ngay,24,0)) | P7: =IF($N7="","",MAX(0,MIN($O7,moc_loi_tu)-MAX($N7,moc_dem_tu))+MAX(0,MIN($O7,moc_dem_den)-MAX($N7,moc_loi_den))) | Q7: =IF($N7="","",MAX(0,MIN($O7,moc_loi_den)-MAX($N7,moc_loi_tu))) | R7: =IF($N7="","",$P7+$Q7) | S7: =IF($N7="","",IF($Q7>0,"Blaze",IF($P7>0,"Spark",""))) | T7: =IF($N7="",0,($P7*rate_gio_bien+$Q7*rate_gio_loi)*IF($G7="Lễ",he_so_le,1)) -> 0 | U7: =IF($N7="",0,IF($S7="Blaze",bca_blaze,IF($S7="Spark",bca_spark,0))*IF($G7="Lễ",he_so_le,1)) -> 0 | V7: =ROUND($T7+$U7,0) -> 0 | W7: =IF(OR($F7<>"OPS",$H7=""),0,ROUND(IF(AND($H7>=TIME(6,0,0),$H7<TIME(8,0,0)),ops_0600_0800,IF(AND($H7>=TIME(8,0,0),$H7<TIME(18,0,0)),ops_0800_1800,IF(AND($H7>=TIME(18,0,0),$H7<TIME(22,0,0)),ops_1800_2200,IF(OR($H7>=TIME(22,0,0),$H7<TIME(1,0,0)),ops_2200_0100,IF(AND($H7>=TIME(1,0,0),$H7<TIME(6,0,0)),ops_0100_0600,0)))))+IF($G7="Lễ",ops_phu_troi_le,0),0)) -> 0 | X7: =$V7+$W7 -> 0 | Y7: =IF(OR($F7<>"OPS",$K7=""),"",IF($K7<=ops_kg_1nguoi,1,ops_nguoi_toi_da)) | Z7: =IF($D7="","",IF(AND($F7="TRUC_DEM",$R7=0),"Ca ngoài khung 22:00–06:00",IF(AND($F7="OPS",$L7<>"",$Y7<>"",$L7<$Y7),"Thiếu người so với định biên","")))
B8: =IF($D8="","",3) | E8: =IFERROR(VLOOKUP(D8,Assumption!$B$69:$C$80,2,0),"") | N8: =IF(OR($F8<>"TRUC_DEM",$H8=""),"",(HOUR($H8)+MINUTE($H8)/60)+IF((HOUR($H8)+MINUTE($H8)/60)<moc_chia_ngay,24,0)) | O8: =IF(OR($F8<>"TRUC_DEM",$I8=""),"",(HOUR($I8)+MINUTE($I8)/60)+IF((HOUR($I8)+MINUTE($I8)/60)<moc_chia_ngay,24,0)) | P8: =IF($N8="","",MAX(0,MIN($O8,moc_loi_tu)-MAX($N8,moc_dem_tu))+MAX(0,MIN($O8,moc_dem_den)-MAX($N8,moc_loi_den))) | Q8: =IF($N8="","",MAX(0,MIN($O8,moc_loi_den)-MAX($N8,moc_loi_tu))) | R8: =IF($N8="","",$P8+$Q8) | S8: =IF($N8="","",IF($Q8>0,"Blaze",IF($P8>0,"Spark",""))) | T8: =IF($N8="",0,($P8*rate_gio_bien+$Q8*rate_gio_loi)*IF($G8="Lễ",he_so_le,1)) -> 0 | U8: =IF($N8="",0,IF($S8="Blaze",bca_blaze,IF($S8="Spark",bca_spark,0))*IF($G8="Lễ",he_so_le,1)) -> 0 | V8: =ROUND($T8+$U8,0) -> 0 | W8: =IF(OR($F8<>"OPS",$H8=""),0,ROUND(IF(AND($H8>=TIME(6,0,0),$H8<TIME(8,0,0)),ops_0600_0800,IF(AND($H8>=TIME(8,0,0),$H8<TIME(18,0,0)),ops_0800_1800,IF(AND($H8>=TIME(18,0,0),$H8<TIME(22,0,0)),ops_1800_2200,IF(OR($H8>=TIME(22,0,0),$H8<TIME(1,0,0)),ops_2200_0100,IF(AND($H8>=TIME(1,0,0),$H8<TIME(6,0,0)),ops_0100_0600,0)))))+IF($G8="Lễ",ops_phu_troi_le,0),0)) -> 0 | X8: =$V8+$W8 -> 0 | Y8: =IF(OR($F8<>"OPS",$K8=""),"",IF($K8<=ops_kg_1nguoi,1,ops_nguoi_toi_da)) | Z8: =IF($D8="","",IF(AND($F8="TRUC_DEM",$R8=0),"Ca ngoài khung 22:00–06:00",IF(AND($F8="OPS",$L8<>"",$Y8<>"",$L8<$Y8),"Thiếu người so với định biên","")))
B9: =IF($D9="","",4) | E9: =IFERROR(VLOOKUP(D9,Assumption!$B$69:$C$80,2,0),"") | N9: =IF(OR($F9<>"TRUC_DEM",$H9=""),"",(HOUR($H9)+MINUTE($H9)/60)+IF((HOUR($H9)+MINUTE($H9)/60)<moc_chia_ngay,24,0)) | O9: =IF(OR($F9<>"TRUC_DEM",$I9=""),"",(HOUR($I9)+MINUTE($I9)/60)+IF((HOUR($I9)+MINUTE($I9)/60)<moc_chia_ngay,24,0)) | P9: =IF($N9="","",MAX(0,MIN($O9,moc_loi_tu)-MAX($N9,moc_dem_tu))+MAX(0,MIN($O9,moc_dem_den)-MAX($N9,moc_loi_den))) | Q9: =IF($N9="","",MAX(0,MIN($O9,moc_loi_den)-MAX($N9,moc_loi_tu))) | R9: =IF($N9="","",$P9+$Q9) | S9: =IF($N9="","",IF($Q9>0,"Blaze",IF($P9>0,"Spark",""))) | T9: =IF($N9="",0,($P9*rate_gio_bien+$Q9*rate_gio_loi)*IF($G9="Lễ",he_so_le,1)) -> 0 | U9: =IF($N9="",0,IF($S9="Blaze",bca_blaze,IF($S9="Spark",bca_spark,0))*IF($G9="Lễ",he_so_le,1)) -> 0 | V9: =ROUND($T9+$U9,0) -> 0 | W9: =IF(OR($F9<>"OPS",$H9=""),0,ROUND(IF(AND($H9>=TIME(6,0,0),$H9<TIME(8,0,0)),ops_0600_0800,IF(AND($H9>=TIME(8,0,0),$H9<TIME(18,0,0)),ops_0800_1800,IF(AND($H9>=TIME(18,0,0),$H9<TIME(22,0,0)),ops_1800_2200,IF(OR($H9>=TIME(22,0,0),$H9<TIME(1,0,0)),ops_2200_0100,IF(AND($H9>=TIME(1,0,0),$H9<TIME(6,0,0)),ops_0100_0600,0)))))+IF($G9="Lễ",ops_phu_troi_le,0),0)) -> 0 | X9: =$V9+$W9 -> 0 | Y9: =IF(OR($F9<>"OPS",$K9=""),"",IF($K9<=ops_kg_1nguoi,1,ops_nguoi_toi_da)) | Z9: =IF($D9="","",IF(AND($F9="TRUC_DEM",$R9=0),"Ca ngoài khung 22:00–06:00",IF(AND($F9="OPS",$L9<>"",$Y9<>"",$L9<$Y9),"Thiếu người so với định biên","")))
B10: =IF($D10="","",5) | E10: =IFERROR(VLOOKUP(D10,Assumption!$B$69:$C$80,2,0),"") | N10: =IF(OR($F10<>"TRUC_DEM",$H10=""),"",(HOUR($H10)+MINUTE($H10)/60)+IF((HOUR($H10)+MINUTE($H10)/60)<moc_chia_ngay,24,0)) | O10: =IF(OR($F10<>"TRUC_DEM",$I10=""),"",(HOUR($I10)+MINUTE($I10)/60)+IF((HOUR($I10)+MINUTE($I10)/60)<moc_chia_ngay,24,0)) | P10: =IF($N10="","",MAX(0,MIN($O10,moc_loi_tu)-MAX($N10,moc_dem_tu))+MAX(0,MIN($O10,moc_dem_den)-MAX($N10,moc_loi_den))) | Q10: =IF($N10="","",MAX(0,MIN($O10,moc_loi_den)-MAX($N10,moc_loi_tu))) | R10: =IF($N10="","",$P10+$Q10) | S10: =IF($N10="","",IF($Q10>0,"Blaze",IF($P10>0,"Spark",""))) | T10: =IF($N10="",0,($P10*rate_gio_bien+$Q10*rate_gio_loi)*IF($G10="Lễ",he_so_le,1)) -> 0 | U10: =IF($N10="",0,IF($S10="Blaze",bca_blaze,IF($S10="Spark",bca_spark,0))*IF($G10="Lễ",he_so_le,1)) -> 0 | V10: =ROUND($T10+$U10,0) -> 0 | W10: =IF(OR($F10<>"OPS",$H10=""),0,ROUND(IF(AND($H10>=TIME(6,0,0),$H10<TIME(8,0,0)),ops_0600_0800,IF(AND($H10>=TIME(8,0,0),$H10<TIME(18,0,0)),ops_0800_1800,IF(AND($H10>=TIME(18,0,0),$H10<TIME(22,0,0)),ops_1800_2200,IF(OR($H10>=TIME(22,0,0),$H10<TIME(1,0,0)),ops_2200_0100,IF(AND($H10>=TIME(1,0,0),$H10<TIME(6,0,0)),ops_0100_0600,0)))))+IF($G10="Lễ",ops_phu_troi_le,0),0)) -> 0 | X10: =$V10+$W10 -> 0 | Y10: =IF(OR($F10<>"OPS",$K10=""),"",IF($K10<=ops_kg_1nguoi,1,ops_nguoi_toi_da)) | Z10: =IF($D10="","",IF(AND($F10="TRUC_DEM",$R10=0),"Ca ngoài khung 22:00–06:00",IF(AND($F10="OPS",$L10<>"",$Y10<>"",$L10<$Y10),"Thiếu người so với định biên","")))
B11: =IF($D11="","",6) | E11: =IFERROR(VLOOKUP(D11,Assumption!$B$69:$C$80,2,0),"") | N11: =IF(OR($F11<>"TRUC_DEM",$H11=""),"",(HOUR($H11)+MINUTE($H11)/60)+IF((HOUR($H11)+MINUTE($H11)/60)<moc_chia_ngay,24,0)) | O11: =IF(OR($F11<>"TRUC_DEM",$I11=""),"",(HOUR($I11)+MINUTE($I11)/60)+IF((HOUR($I11)+MINUTE($I11)/60)<moc_chia_ngay,24,0)) | P11: =IF($N11="","",MAX(0,MIN($O11,moc_loi_tu)-MAX($N11,moc_dem_tu))+MAX(0,MIN($O11,moc_dem_den)-MAX($N11,moc_loi_den))) | Q11: =IF($N11="","",MAX(0,MIN($O11,moc_loi_den)-MAX($N11,moc_loi_tu))) | R11: =IF($N11="","",$P11+$Q11) | S11: =IF($N11="","",IF($Q11>0,"Blaze",IF($P11>0,"Spark",""))) | T11: =IF($N11="",0,($P11*rate_gio_bien+$Q11*rate_gio_loi)*IF($G11="Lễ",he_so_le,1)) -> 0 | U11: =IF($N11="",0,IF($S11="Blaze",bca_blaze,IF($S11="Spark",bca_spark,0))*IF($G11="Lễ",he_so_le,1)) -> 0 | V11: =ROUND($T11+$U11,0) -> 0 | W11: =IF(OR($F11<>"OPS",$H11=""),0,ROUND(IF(AND($H11>=TIME(6,0,0),$H11<TIME(8,0,0)),ops_0600_0800,IF(AND($H11>=TIME(8,0,0),$H11<TIME(18,0,0)),ops_0800_1800,IF(AND($H11>=TIME(18,0,0),$H11<TIME(22,0,0)),ops_1800_2200,IF(OR($H11>=TIME(22,0,0),$H11<TIME(1,0,0)),ops_2200_0100,IF(AND($H11>=TIME(1,0,0),$H11<TIME(6,0,0)),ops_0100_0600,0)))))+IF($G11="Lễ",ops_phu_troi_le,0),0)) -> 0 | X11: =$V11+$W11 -> 0 | Y11: =IF(OR($F11<>"OPS",$K11=""),"",IF($K11<=ops_kg_1nguoi,1,ops_nguoi_toi_da)) | Z11: =IF($D11="","",IF(AND($F11="TRUC_DEM",$R11=0),"Ca ngoài khung 22:00–06:00",IF(AND($F11="OPS",$L11<>"",$Y11<>"",$L11<$Y11),"Thiếu người so với định biên","")))
B12: =IF($D12="","",7) | E12: =IFERROR(VLOOKUP(D12,Assumption!$B$69:$C$80,2,0),"") | N12: =IF(OR($F12<>"TRUC_DEM",$H12=""),"",(HOUR($H12)+MINUTE($H12)/60)+IF((HOUR($H12)+MINUTE($H12)/60)<moc_chia_ngay,24,0)) | O12: =IF(OR($F12<>"TRUC_DEM",$I12=""),"",(HOUR($I12)+MINUTE($I12)/60)+IF((HOUR($I12)+MINUTE($I12)/60)<moc_chia_ngay,24,0)) | P12: =IF($N12="","",MAX(0,MIN($O12,moc_loi_tu)-MAX($N12,moc_dem_tu))+MAX(0,MIN($O12,moc_dem_den)-MAX($N12,moc_loi_den))) | Q12: =IF($N12="","",MAX(0,MIN($O12,moc_loi_den)-MAX($N12,moc_loi_tu))) | R12: =IF($N12="","",$P12+$Q12) | S12: =IF($N12="","",IF($Q12>0,"Blaze",IF($P12>0,"Spark",""))) | T12: =IF($N12="",0,($P12*rate_gio_bien+$Q12*rate_gio_loi)*IF($G12="Lễ",he_so_le,1)) -> 0 | U12: =IF($N12="",0,IF($S12="Blaze",bca_blaze,IF($S12="Spark",bca_spark,0))*IF($G12="Lễ",he_so_le,1)) -> 0 | V12: =ROUND($T12+$U12,0) -> 0 | W12: =IF(OR($F12<>"OPS",$H12=""),0,ROUND(IF(AND($H12>=TIME(6,0,0),$H12<TIME(8,0,0)),ops_0600_0800,IF(AND($H12>=TIME(8,0,0),$H12<TIME(18,0,0)),ops_0800_1800,IF(AND($H12>=TIME(18,0,0),$H12<TIME(22,0,0)),ops_1800_2200,IF(OR($H12>=TIME(22,0,0),$H12<TIME(1,0,0)),ops_2200_0100,IF(AND($H12>=TIME(1,0,0),$H12<TIME(6,0,0)),ops_0100_0600,0)))))+IF($G12="Lễ",ops_phu_troi_le,0),0)) -> 0 | X12: =$V12+$W12 -> 0 | Y12: =IF(OR($F12<>"OPS",$K12=""),"",IF($K12<=ops_kg_1nguoi,1,ops_nguoi_toi_da)) | Z12: =IF($D12="","",IF(AND($F12="TRUC_DEM",$R12=0),"Ca ngoài khung 22:00–06:00",IF(AND($F12="OPS",$L12<>"",$Y12<>"",$L12<$Y12),"Thiếu người so với định biên","")))
B13: =IF($D13="","",8) | E13: =IFERROR(VLOOKUP(D13,Assumption!$B$69:$C$80,2,0),"") | N13: =IF(OR($F13<>"TRUC_DEM",$H13=""),"",(HOUR($H13)+MINUTE($H13)/60)+IF((HOUR($H13)+MINUTE($H13)/60)<moc_chia_ngay,24,0)) | O13: =IF(OR($F13<>"TRUC_DEM",$I13=""),"",(HOUR($I13)+MINUTE($I13)/60)+IF((HOUR($I13)+MINUTE($I13)/60)<moc_chia_ngay,24,0)) | P13: =IF($N13="","",MAX(0,MIN($O13,moc_loi_tu)-MAX($N13,moc_dem_tu))+MAX(0,MIN($O13,moc_dem_den)-MAX($N13,moc_loi_den))) | Q13: =IF($N13="","",MAX(0,MIN($O13,moc_loi_den)-MAX($N13,moc_loi_tu))) | R13: =IF($N13="","",$P13+$Q13) | S13: =IF($N13="","",IF($Q13>0,"Blaze",IF($P13>0,"Spark",""))) | T13: =IF($N13="",0,($P13*rate_gio_bien+$Q13*rate_gio_loi)*IF($G13="Lễ",he_so_le,1)) -> 0 | U13: =IF($N13="",0,IF($S13="Blaze",bca_blaze,IF($S13="Spark",bca_spark,0))*IF($G13="Lễ",he_so_le,1)) -> 0 | V13: =ROUND($T13+$U13,0) -> 0 | W13: =IF(OR($F13<>"OPS",$H13=""),0,ROUND(IF(AND($H13>=TIME(6,0,0),$H13<TIME(8,0,0)),ops_0600_0800,IF(AND($H13>=TIME(8,0,0),$H13<TIME(18,0,0)),ops_0800_1800,IF(AND($H13>=TIME(18,0,0),$H13<TIME(22,0,0)),ops_1800_2200,IF(OR($H13>=TIME(22,0,0),$H13<TIME(1,0,0)),ops_2200_0100,IF(AND($H13>=TIME(1,0,0),$H13<TIME(6,0,0)),ops_0100_0600,0)))))+IF($G13="Lễ",ops_phu_troi_le,0),0)) -> 0 | X13: =$V13+$W13 -> 0 | Y13: =IF(OR($F13<>"OPS",$K13=""),"",IF($K13<=ops_kg_1nguoi,1,ops_nguoi_toi_da)) | Z13: =IF($D13="","",IF(AND($F13="TRUC_DEM",$R13=0),"Ca ngoài khung 22:00–06:00",IF(AND($F13="OPS",$L13<>"",$Y13<>"",$L13<$Y13),"Thiếu người so với định biên","")))
B14: =IF($D14="","",9) | E14: =IFERROR(VLOOKUP(D14,Assumption!$B$69:$C$80,2,0),"") | N14: =IF(OR($F14<>"TRUC_DEM",$H14=""),"",(HOUR($H14)+MINUTE($H14)/60)+IF((HOUR($H14)+MINUTE($H14)/60)<moc_chia_ngay,24,0)) | O14: =IF(OR($F14<>"TRUC_DEM",$I14=""),"",(HOUR($I14)+MINUTE($I14)/60)+IF((HOUR($I14)+MINUTE($I14)/60)<moc_chia_ngay,24,0)) | P14: =IF($N14="","",MAX(0,MIN($O14,moc_loi_tu)-MAX($N14,moc_dem_tu))+MAX(0,MIN($O14,moc_dem_den)-MAX($N14,moc_loi_den))) | Q14: =IF($N14="","",MAX(0,MIN($O14,moc_loi_den)-MAX($N14,moc_loi_tu))) | R14: =IF($N14="","",$P14+$Q14) | S14: =IF($N14="","",IF($Q14>0,"Blaze",IF($P14>0,"Spark",""))) | T14: =IF($N14="",0,($P14*rate_gio_bien+$Q14*rate_gio_loi)*IF($G14="Lễ",he_so_le,1)) -> 0 | U14: =IF($N14="",0,IF($S14="Blaze",bca_blaze,IF($S14="Spark",bca_spark,0))*IF($G14="Lễ",he_so_le,1)) -> 0 | V14: =ROUND($T14+$U14,0) -> 0 | W14: =IF(OR($F14<>"OPS",$H14=""),0,ROUND(IF(AND($H14>=TIME(6,0,0),$H14<TIME(8,0,0)),ops_0600_0800,IF(AND($H14>=TIME(8,0,0),$H14<TIME(18,0,0)),ops_0800_1800,IF(AND($H14>=TIME(18,0,0),$H14<TIME(22,0,0)),ops_1800_2200,IF(OR($H14>=TIME(22,0,0),$H14<TIME(1,0,0)),ops_2200_0100,IF(AND($H14>=TIME(1,0,0),$H14<TIME(6,0,0)),ops_0100_0600,0)))))+IF($G14="Lễ",ops_phu_troi_le,0),0)) -> 0 | X14: =$V14+$W14 -> 0 | Y14: =IF(OR($F14<>"OPS",$K14=""),"",IF($K14<=ops_kg_1nguoi,1,ops_nguoi_toi_da)) | Z14: =IF($D14="","",IF(AND($F14="TRUC_DEM",$R14=0),"Ca ngoài khung 22:00–06:00",IF(AND($F14="OPS",$L14<>"",$Y14<>"",$L14<$Y14),"Thiếu người so với định biên","")))
B15: =IF($D15="","",10) | E15: =IFERROR(VLOOKUP(D15,Assumption!$B$69:$C$80,2,0),"") | N15: =IF(OR($F15<>"TRUC_DEM",$H15=""),"",(HOUR($H15)+MINUTE($H15)/60)+IF((HOUR($H15)+MINUTE($H15)/60)<moc_chia_ngay,24,0)) | O15: =IF(OR($F15<>"TRUC_DEM",$I15=""),"",(HOUR($I15)+MINUTE($I15)/60)+IF((HOUR($I15)+MINUTE($I15)/60)<moc_chia_ngay,24,0)) | P15: =IF($N15="","",MAX(0,MIN($O15,moc_loi_tu)-MAX($N15,moc_dem_tu))+MAX(0,MIN($O15,moc_dem_den)-MAX($N15,moc_loi_den))) | Q15: =IF($N15="","",MAX(0,MIN($O15,moc_loi_den)-MAX($N15,moc_loi_tu))) | R15: =IF($N15="","",$P15+$Q15) | S15: =IF($N15="","",IF($Q15>0,"Blaze",IF($P15>0,"Spark",""))) | T15: =IF($N15="",0,($P15*rate_gio_bien+$Q15*rate_gio_loi)*IF($G15="Lễ",he_so_le,1)) -> 0 | U15: =IF($N15="",0,IF($S15="Blaze",bca_blaze,IF($S15="Spark",bca_spark,0))*IF($G15="Lễ",he_so_le,1)) -> 0 | V15: =ROUND($T15+$U15,0) -> 0 | W15: =IF(OR($F15<>"OPS",$H15=""),0,ROUND(IF(AND($H15>=TIME(6,0,0),$H15<TIME(8,0,0)),ops_0600_0800,IF(AND($H15>=TIME(8,0,0),$H15<TIME(18,0,0)),ops_0800_1800,IF(AND($H15>=TIME(18,0,0),$H15<TIME(22,0,0)),ops_1800_2200,IF(OR($H15>=TIME(22,0,0),$H15<TIME(1,0,0)),ops_2200_0100,IF(AND($H15>=TIME(1,0,0),$H15<TIME(6,0,0)),ops_0100_0600,0)))))+IF($G15="Lễ",ops_phu_troi_le,0),0)) -> 0 | X15: =$V15+$W15 -> 0 | Y15: =IF(OR($F15<>"OPS",$K15=""),"",IF($K15<=ops_kg_1nguoi,1,ops_nguoi_toi_da)) | Z15: =IF($D15="","",IF(AND($F15="TRUC_DEM",$R15=0),"Ca ngoài khung 22:00–06:00",IF(AND($F15="OPS",$L15<>"",$Y15<>"",$L15<$Y15),"Thiếu người so với định biên","")))
B16: =IF($D16="","",11) | E16: =IFERROR(VLOOKUP(D16,Assumption!$B$69:$C$80,2,0),"") | N16: =IF(OR($F16<>"TRUC_DEM",$H16=""),"",(HOUR($H16)+MINUTE($H16)/60)+IF((HOUR($H16)+MINUTE($H16)/60)<moc_chia_ngay,24,0)) | O16: =IF(OR($F16<>"TRUC_DEM",$I16=""),"",(HOUR($I16)+MINUTE($I16)/60)+IF((HOUR($I16)+MINUTE($I16)/60)<moc_chia_ngay,24,0)) | P16: =IF($N16="","",MAX(0,MIN($O16,moc_loi_tu)-MAX($N16,moc_dem_tu))+MAX(0,MIN($O16,moc_dem_den)-MAX($N16,moc_loi_den))) | Q16: =IF($N16="","",MAX(0,MIN($O16,moc_loi_den)-MAX($N16,moc_loi_tu))) | R16: =IF($N16="","",$P16+$Q16) | S16: =IF($N16="","",IF($Q16>0,"Blaze",IF($P16>0,"Spark",""))) | T16: =IF($N16="",0,($P16*rate_gio_bien+$Q16*rate_gio_loi)*IF($G16="Lễ",he_so_le,1)) -> 0 | U16: =IF($N16="",0,IF($S16="Blaze",bca_blaze,IF($S16="Spark",bca_spark,0))*IF($G16="Lễ",he_so_le,1)) -> 0 | V16: =ROUND($T16+$U16,0) -> 0 | W16: =IF(OR($F16<>"OPS",$H16=""),0,ROUND(IF(AND($H16>=TIME(6,0,0),$H16<TIME(8,0,0)),ops_0600_0800,IF(AND($H16>=TIME(8,0,0),$H16<TIME(18,0,0)),ops_0800_1800,IF(AND($H16>=TIME(18,0,0),$H16<TIME(22,0,0)),ops_1800_2200,IF(OR($H16>=TIME(22,0,0),$H16<TIME(1,0,0)),ops_2200_0100,IF(AND($H16>=TIME(1,0,0),$H16<TIME(6,0,0)),ops_0100_0600,0)))))+IF($G16="Lễ",ops_phu_troi_le,0),0)) -> 0 | X16: =$V16+$W16 -> 0 | Y16: =IF(OR($F16<>"OPS",$K16=""),"",IF($K16<=ops_kg_1nguoi,1,ops_nguoi_toi_da)) | Z16: =IF($D16="","",IF(AND($F16="TRUC_DEM",$R16=0),"Ca ngoài khung 22:00–06:00",IF(AND($F16="OPS",$L16<>"",$Y16<>"",$L16<$Y16),"Thiếu người so với định biên","")))
B17: =IF($D17="","",12) | E17: =IFERROR(VLOOKUP(D17,Assumption!$B$69:$C$80,2,0),"") | N17: =IF(OR($F17<>"TRUC_DEM",$H17=""),"",(HOUR($H17)+MINUTE($H17)/60)+IF((HOUR($H17)+MINUTE($H17)/60)<moc_chia_ngay,24,0)) | O17: =IF(OR($F17<>"TRUC_DEM",$I17=""),"",(HOUR($I17)+MINUTE($I17)/60)+IF((HOUR($I17)+MINUTE($I17)/60)<moc_chia_ngay,24,0)) | P17: =IF($N17="","",MAX(0,MIN($O17,moc_loi_tu)-MAX($N17,moc_dem_tu))+MAX(0,MIN($O17,moc_dem_den)-MAX($N17,moc_loi_den))) | Q17: =IF($N17="","",MAX(0,MIN($O17,moc_loi_den)-MAX($N17,moc_loi_tu))) | R17: =IF($N17="","",$P17+$Q17) | S17: =IF($N17="","",IF($Q17>0,"Blaze",IF($P17>0,"Spark",""))) | T17: =IF($N17="",0,($P17*rate_gio_bien+$Q17*rate_gio_loi)*IF($G17="Lễ",he_so_le,1)) -> 0 | U17: =IF($N17="",0,IF($S17="Blaze",bca_blaze,IF($S17="Spark",bca_spark,0))*IF($G17="Lễ",he_so_le,1)) -> 0 | V17: =ROUND($T17+$U17,0) -> 0 | W17: =IF(OR($F17<>"OPS",$H17=""),0,ROUND(IF(AND($H17>=TIME(6,0,0),$H17<TIME(8,0,0)),ops_0600_0800,IF(AND($H17>=TIME(8,0,0),$H17<TIME(18,0,0)),ops_0800_1800,IF(AND($H17>=TIME(18,0,0),$H17<TIME(22,0,0)),ops_1800_2200,IF(OR($H17>=TIME(22,0,0),$H17<TIME(1,0,0)),ops_2200_0100,IF(AND($H17>=TIME(1,0,0),$H17<TIME(6,0,0)),ops_0100_0600,0)))))+IF($G17="Lễ",ops_phu_troi_le,0),0)) -> 0 | X17: =$V17+$W17 -> 0 | Y17: =IF(OR($F17<>"OPS",$K17=""),"",IF($K17<=ops_kg_1nguoi,1,ops_nguoi_toi_da)) | Z17: =IF($D17="","",IF(AND($F17="TRUC_DEM",$R17=0),"Ca ngoài khung 22:00–06:00",IF(AND($F17="OPS",$L17<>"",$Y17<>"",$L17<$Y17),"Thiếu người so với định biên","")))
B18: =IF($D18="","",13) | E18: =IFERROR(VLOOKUP(D18,Assumption!$B$69:$C$80,2,0),"") | N18: =IF(OR($F18<>"TRUC_DEM",$H18=""),"",(HOUR($H18)+MINUTE($H18)/60)+IF((HOUR($H18)+MINUTE($H18)/60)<moc_chia_ngay,24,0)) | O18: =IF(OR($F18<>"TRUC_DEM",$I18=""),"",(HOUR($I18)+MINUTE($I18)/60)+IF((HOUR($I18)+MINUTE($I18)/60)<moc_chia_ngay,24,0)) | P18: =IF($N18="","",MAX(0,MIN($O18,moc_loi_tu)-MAX($N18,moc_dem_tu))+MAX(0,MIN($O18,moc_dem_den)-MAX($N18,moc_loi_den))) | Q18: =IF($N18="","",MAX(0,MIN($O18,moc_loi_den)-MAX($N18,moc_loi_tu))) | R18: =IF($N18="","",$P18+$Q18) | S18: =IF($N18="","",IF($Q18>0,"Blaze",IF($P18>0,"Spark",""))) | T18: =IF($N18="",0,($P18*rate_gio_bien+$Q18*rate_gio_loi)*IF($G18="Lễ",he_so_le,1)) -> 0 | U18: =IF($N18="",0,IF($S18="Blaze",bca_blaze,IF($S18="Spark",bca_spark,0))*IF($G18="Lễ",he_so_le,1)) -> 0 | V18: =ROUND($T18+$U18,0) -> 0 | W18: =IF(OR($F18<>"OPS",$H18=""),0,ROUND(IF(AND($H18>=TIME(6,0,0),$H18<TIME(8,0,0)),ops_0600_0800,IF(AND($H18>=TIME(8,0,0),$H18<TIME(18,0,0)),ops_0800_1800,IF(AND($H18>=TIME(18,0,0),$H18<TIME(22,0,0)),ops_1800_2200,IF(OR($H18>=TIME(22,0,0),$H18<TIME(1,0,0)),ops_2200_0100,IF(AND($H18>=TIME(1,0,0),$H18<TIME(6,0,0)),ops_0100_0600,0)))))+IF($G18="Lễ",ops_phu_troi_le,0),0)) -> 0 | X18: =$V18+$W18 -> 0 | Y18: =IF(OR($F18<>"OPS",$K18=""),"",IF($K18<=ops_kg_1nguoi,1,ops_nguoi_toi_da)) | Z18: =IF($D18="","",IF(AND($F18="TRUC_DEM",$R18=0),"Ca ngoài khung 22:00–06:00",IF(AND($F18="OPS",$L18<>"",$Y18<>"",$L18<$Y18),"Thiếu người so với định biên","")))
B19: =IF($D19="","",14) | E19: =IFERROR(VLOOKUP(D19,Assumption!$B$69:$C$80,2,0),"") | N19: =IF(OR($F19<>"TRUC_DEM",$H19=""),"",(HOUR($H19)+MINUTE($H19)/60)+IF((HOUR($H19)+MINUTE($H19)/60)<moc_chia_ngay,24,0)) | O19: =IF(OR($F19<>"TRUC_DEM",$I19=""),"",(HOUR($I19)+MINUTE($I19)/60)+IF((HOUR($I19)+MINUTE($I19)/60)<moc_chia_ngay,24,0)) | P19: =IF($N19="","",MAX(0,MIN($O19,moc_loi_tu)-MAX($N19,moc_dem_tu))+MAX(0,MIN($O19,moc_dem_den)-MAX($N19,moc_loi_den))) | Q19: =IF($N19="","",MAX(0,MIN($O19,moc_loi_den)-MAX($N19,moc_loi_tu))) | R19: =IF($N19="","",$P19+$Q19) | S19: =IF($N19="","",IF($Q19>0,"Blaze",IF($P19>0,"Spark",""))) | T19: =IF($N19="",0,($P19*rate_gio_bien+$Q19*rate_gio_loi)*IF($G19="Lễ",he_so_le,1)) -> 0 | U19: =IF($N19="",0,IF($S19="Blaze",bca_blaze,IF($S19="Spark",bca_spark,0))*IF($G19="Lễ",he_so_le,1)) -> 0 | V19: =ROUND($T19+$U19,0) -> 0 | W19: =IF(OR($F19<>"OPS",$H19=""),0,ROUND(IF(AND($H19>=TIME(6,0,0),$H19<TIME(8,0,0)),ops_0600_0800,IF(AND($H19>=TIME(8,0,0),$H19<TIME(18,0,0)),ops_0800_1800,IF(AND($H19>=TIME(18,0,0),$H19<TIME(22,0,0)),ops_1800_2200,IF(OR($H19>=TIME(22,0,0),$H19<TIME(1,0,0)),ops_2200_0100,IF(AND($H19>=TIME(1,0,0),$H19<TIME(6,0,0)),ops_0100_0600,0)))))+IF($G19="Lễ",ops_phu_troi_le,0),0)) -> 0 | X19: =$V19+$W19 -> 0 | Y19: =IF(OR($F19<>"OPS",$K19=""),"",IF($K19<=ops_kg_1nguoi,1,ops_nguoi_toi_da)) | Z19: =IF($D19="","",IF(AND($F19="TRUC_DEM",$R19=0),"Ca ngoài khung 22:00–06:00",IF(AND($F19="OPS",$L19<>"",$Y19<>"",$L19<$Y19),"Thiếu người so với định biên","")))
B20: =IF($D20="","",15) | E20: =IFERROR(VLOOKUP(D20,Assumption!$B$69:$C$80,2,0),"") | N20: =IF(OR($F20<>"TRUC_DEM",$H20=""),"",(HOUR($H20)+MINUTE($H20)/60)+IF((HOUR($H20)+MINUTE($H20)/60)<moc_chia_ngay,24,0)) | O20: =IF(OR($F20<>"TRUC_DEM",$I20=""),"",(HOUR($I20)+MINUTE($I20)/60)+IF((HOUR($I20)+MINUTE($I20)/60)<moc_chia_ngay,24,0)) | P20: =IF($N20="","",MAX(0,MIN($O20,moc_loi_tu)-MAX($N20,moc_dem_tu))+MAX(0,MIN($O20,moc_dem_den)-MAX($N20,moc_loi_den))) | Q20: =IF($N20="","",MAX(0,MIN($O20,moc_loi_den)-MAX($N20,moc_loi_tu))) | R20: =IF($N20="","",$P20+$Q20) | S20: =IF($N20="","",IF($Q20>0,"Blaze",IF($P20>0,"Spark",""))) | T20: =IF($N20="",0,($P20*rate_gio_bien+$Q20*rate_gio_loi)*IF($G20="Lễ",he_so_le,1)) -> 0 | U20: =IF($N20="",0,IF($S20="Blaze",bca_blaze,IF($S20="Spark",bca_spark,0))*IF($G20="Lễ",he_so_le,1)) -> 0 | V20: =ROUND($T20+$U20,0) -> 0 | W20: =IF(OR($F20<>"OPS",$H20=""),0,ROUND(IF(AND($H20>=TIME(6,0,0),$H20<TIME(8,0,0)),ops_0600_0800,IF(AND($H20>=TIME(8,0,0),$H20<TIME(18,0,0)),ops_0800_1800,IF(AND($H20>=TIME(18,0,0),$H20<TIME(22,0,0)),ops_1800_2200,IF(OR($H20>=TIME(22,0,0),$H20<TIME(1,0,0)),ops_2200_0100,IF(AND($H20>=TIME(1,0,0),$H20<TIME(6,0,0)),ops_0100_0600,0)))))+IF($G20="Lễ",ops_phu_troi_le,0),0)) -> 0 | X20: =$V20+$W20 -> 0 | Y20: =IF(OR($F20<>"OPS",$K20=""),"",IF($K20<=ops_kg_1nguoi,1,ops_nguoi_toi_da)) | Z20: =IF($D20="","",IF(AND($F20="TRUC_DEM",$R20=0),"Ca ngoài khung 22:00–06:00",IF(AND($F20="OPS",$L20<>"",$Y20<>"",$L20<$Y20),"Thiếu người so với định biên","")))
B21: =IF($D21="","",16) | E21: =IFERROR(VLOOKUP(D21,Assumption!$B$69:$C$80,2,0),"") | N21: =IF(OR($F21<>"TRUC_DEM",$H21=""),"",(HOUR($H21)+MINUTE($H21)/60)+IF((HOUR($H21)+MINUTE($H21)/60)<moc_chia_ngay,24,0)) | O21: =IF(OR($F21<>"TRUC_DEM",$I21=""),"",(HOUR($I21)+MINUTE($I21)/60)+IF((HOUR($I21)+MINUTE($I21)/60)<moc_chia_ngay,24,0)) | P21: =IF($N21="","",MAX(0,MIN($O21,moc_loi_tu)-MAX($N21,moc_dem_tu))+MAX(0,MIN($O21,moc_dem_den)-MAX($N21,moc_loi_den))) | Q21: =IF($N21="","",MAX(0,MIN($O21,moc_loi_den)-MAX($N21,moc_loi_tu))) | R21: =IF($N21="","",$P21+$Q21) | S21: =IF($N21="","",IF($Q21>0,"Blaze",IF($P21>0,"Spark",""))) | T21: =IF($N21="",0,($P21*rate_gio_bien+$Q21*rate_gio_loi)*IF($G21="Lễ",he_so_le,1)) -> 0 | U21: =IF($N21="",0,IF($S21="Blaze",bca_blaze,IF($S21="Spark",bca_spark,0))*IF($G21="Lễ",he_so_le,1)) -> 0 | V21: =ROUND($T21+$U21,0) -> 0 | W21: =IF(OR($F21<>"OPS",$H21=""),0,ROUND(IF(AND($H21>=TIME(6,0,0),$H21<TIME(8,0,0)),ops_0600_0800,IF(AND($H21>=TIME(8,0,0),$H21<TIME(18,0,0)),ops_0800_1800,IF(AND($H21>=TIME(18,0,0),$H21<TIME(22,0,0)),ops_1800_2200,IF(OR($H21>=TIME(22,0,0),$H21<TIME(1,0,0)),ops_2200_0100,IF(AND($H21>=TIME(1,0,0),$H21<TIME(6,0,0)),ops_0100_0600,0)))))+IF($G21="Lễ",ops_phu_troi_le,0),0)) -> 0 | X21: =$V21+$W21 -> 0 | Y21: =IF(OR($F21<>"OPS",$K21=""),"",IF($K21<=ops_kg_1nguoi,1,ops_nguoi_toi_da)) | Z21: =IF($D21="","",IF(AND($F21="TRUC_DEM",$R21=0),"Ca ngoài khung 22:00–06:00",IF(AND($F21="OPS",$L21<>"",$Y21<>"",$L21<$Y21),"Thiếu người so với định biên","")))
B22: =IF($D22="","",17) | E22: =IFERROR(VLOOKUP(D22,Assumption!$B$69:$C$80,2,0),"") | N22: =IF(OR($F22<>"TRUC_DEM",$H22=""),"",(HOUR($H22)+MINUTE($H22)/60)+IF((HOUR($H22)+MINUTE($H22)/60)<moc_chia_ngay,24,0)) | O22: =IF(OR($F22<>"TRUC_DEM",$I22=""),"",(HOUR($I22)+MINUTE($I22)/60)+IF((HOUR($I22)+MINUTE($I22)/60)<moc_chia_ngay,24,0)) | P22: =IF($N22="","",MAX(0,MIN($O22,moc_loi_tu)-MAX($N22,moc_dem_tu))+MAX(0,MIN($O22,moc_dem_den)-MAX($N22,moc_loi_den))) | Q22: =IF($N22="","",MAX(0,MIN($O22,moc_loi_den)-MAX($N22,moc_loi_tu))) | R22: =IF($N22="","",$P22+$Q22) | S22: =IF($N22="","",IF($Q22>0,"Blaze",IF($P22>0,"Spark",""))) | T22: =IF($N22="",0,($P22*rate_gio_bien+$Q22*rate_gio_loi)*IF($G22="Lễ",he_so_le,1)) -> 0 | U22: =IF($N22="",0,IF($S22="Blaze",bca_blaze,IF($S22="Spark",bca_spark,0))*IF($G22="Lễ",he_so_le,1)) -> 0 | V22: =ROUND($T22+$U22,0) -> 0 | W22: =IF(OR($F22<>"OPS",$H22=""),0,ROUND(IF(AND($H22>=TIME(6,0,0),$H22<TIME(8,0,0)),ops_0600_0800,IF(AND($H22>=TIME(8,0,0),$H22<TIME(18,0,0)),ops_0800_1800,IF(AND($H22>=TIME(18,0,0),$H22<TIME(22,0,0)),ops_1800_2200,IF(OR($H22>=TIME(22,0,0),$H22<TIME(1,0,0)),ops_2200_0100,IF(AND($H22>=TIME(1,0,0),$H22<TIME(6,0,0)),ops_0100_0600,0)))))+IF($G22="Lễ",ops_phu_troi_le,0),0)) -> 0 | X22: =$V22+$W22 -> 0 | Y22: =IF(OR($F22<>"OPS",$K22=""),"",IF($K22<=ops_kg_1nguoi,1,ops_nguoi_toi_da)) | Z22: =IF($D22="","",IF(AND($F22="TRUC_DEM",$R22=0),"Ca ngoài khung 22:00–06:00",IF(AND($F22="OPS",$L22<>"",$Y22<>"",$L22<$Y22),"Thiếu người so với định biên","")))
B23: =IF($D23="","",18) | E23: =IFERROR(VLOOKUP(D23,Assumption!$B$69:$C$80,2,0),"") | N23: =IF(OR($F23<>"TRUC_DEM",$H23=""),"",(HOUR($H23)+MINUTE($H23)/60)+IF((HOUR($H23)+MINUTE($H23)/60)<moc_chia_ngay,24,0)) | O23: =IF(OR($F23<>"TRUC_DEM",$I23=""),"",(HOUR($I23)+MINUTE($I23)/60)+IF((HOUR($I23)+MINUTE($I23)/60)<moc_chia_ngay,24,0)) | P23: =IF($N23="","",MAX(0,MIN($O23,moc_loi_tu)-MAX($N23,moc_dem_tu))+MAX(0,MIN($O23,moc_dem_den)-MAX($N23,moc_loi_den))) | Q23: =IF($N23="","",MAX(0,MIN($O23,moc_loi_den)-MAX($N23,moc_loi_tu))) | R23: =IF($N23="","",$P23+$Q23) | S23: =IF($N23="","",IF($Q23>0,"Blaze",IF($P23>0,"Spark",""))) | T23: =IF($N23="",0,($P23*rate_gio_bien+$Q23*rate_gio_loi)*IF($G23="Lễ",he_so_le,1)) -> 0 | U23: =IF($N23="",0,IF($S23="Blaze",bca_blaze,IF($S23="Spark",bca_spark,0))*IF($G23="Lễ",he_so_le,1)) -> 0 | V23: =ROUND($T23+$U23,0) -> 0 | W23: =IF(OR($F23<>"OPS",$H23=""),0,ROUND(IF(AND($H23>=TIME(6,0,0),$H23<TIME(8,0,0)),ops_0600_0800,IF(AND($H23>=TIME(8,0,0),$H23<TIME(18,0,0)),ops_0800_1800,IF(AND($H23>=TIME(18,0,0),$H23<TIME(22,0,0)),ops_1800_2200,IF(OR($H23>=TIME(22,0,0),$H23<TIME(1,0,0)),ops_2200_0100,IF(AND($H23>=TIME(1,0,0),$H23<TIME(6,0,0)),ops_0100_0600,0)))))+IF($G23="Lễ",ops_phu_troi_le,0),0)) -> 0 | X23: =$V23+$W23 -> 0 | Y23: =IF(OR($F23<>"OPS",$K23=""),"",IF($K23<=ops_kg_1nguoi,1,ops_nguoi_toi_da)) | Z23: =IF($D23="","",IF(AND($F23="TRUC_DEM",$R23=0),"Ca ngoài khung 22:00–06:00",IF(AND($F23="OPS",$L23<>"",$Y23<>"",$L23<$Y23),"Thiếu người so với định biên","")))
B24: =IF($D24="","",19) | E24: =IFERROR(VLOOKUP(D24,Assumption!$B$69:$C$80,2,0),"") | N24: =IF(OR($F24<>"TRUC_DEM",$H24=""),"",(HOUR($H24)+MINUTE($H24)/60)+IF((HOUR($H24)+MINUTE($H24)/60)<moc_chia_ngay,24,0)) | O24: =IF(OR($F24<>"TRUC_DEM",$I24=""),"",(HOUR($I24)+MINUTE($I24)/60)+IF((HOUR($I24)+MINUTE($I24)/60)<moc_chia_ngay,24,0)) | P24: =IF($N24="","",MAX(0,MIN($O24,moc_loi_tu)-MAX($N24,moc_dem_tu))+MAX(0,MIN($O24,moc_dem_den)-MAX($N24,moc_loi_den))) | Q24: =IF($N24="","",MAX(0,MIN($O24,moc_loi_den)-MAX($N24,moc_loi_tu))) | R24: =IF($N24="","",$P24+$Q24) | S24: =IF($N24="","",IF($Q24>0,"Blaze",IF($P24>0,"Spark",""))) | T24: =IF($N24="",0,($P24*rate_gio_bien+$Q24*rate_gio_loi)*IF($G24="Lễ",he_so_le,1)) -> 0 | U24: =IF($N24="",0,IF($S24="Blaze",bca_blaze,IF($S24="Spark",bca_spark,0))*IF($G24="Lễ",he_so_le,1)) -> 0 | V24: =ROUND($T24+$U24,0) -> 0 | W24: =IF(OR($F24<>"OPS",$H24=""),0,ROUND(IF(AND($H24>=TIME(6,0,0),$H24<TIME(8,0,0)),ops_0600_0800,IF(AND($H24>=TIME(8,0,0),$H24<TIME(18,0,0)),ops_0800_1800,IF(AND($H24>=TIME(18,0,0),$H24<TIME(22,0,0)),ops_1800_2200,IF(OR($H24>=TIME(22,0,0),$H24<TIME(1,0,0)),ops_2200_0100,IF(AND($H24>=TIME(1,0,0),$H24<TIME(6,0,0)),ops_0100_0600,0)))))+IF($G24="Lễ",ops_phu_troi_le,0),0)) -> 0 | X24: =$V24+$W24 -> 0 | Y24: =IF(OR($F24<>"OPS",$K24=""),"",IF($K24<=ops_kg_1nguoi,1,ops_nguoi_toi_da)) | Z24: =IF($D24="","",IF(AND($F24="TRUC_DEM",$R24=0),"Ca ngoài khung 22:00–06:00",IF(AND($F24="OPS",$L24<>"",$Y24<>"",$L24<$Y24),"Thiếu người so với định biên","")))
B25: =IF($D25="","",20) | E25: =IFERROR(VLOOKUP(D25,Assumption!$B$69:$C$80,2,0),"") | N25: =IF(OR($F25<>"TRUC_DEM",$H25=""),"",(HOUR($H25)+MINUTE($H25)/60)+IF((HOUR($H25)+MINUTE($H25)/60)<moc_chia_ngay,24,0)) | O25: =IF(OR($F25<>"TRUC_DEM",$I25=""),"",(HOUR($I25)+MINUTE($I25)/60)+IF((HOUR($I25)+MINUTE($I25)/60)<moc_chia_ngay,24,0)) | P25: =IF($N25="","",MAX(0,MIN($O25,moc_loi_tu)-MAX($N25,moc_dem_tu))+MAX(0,MIN($O25,moc_dem_den)-MAX($N25,moc_loi_den))) | Q25: =IF($N25="","",MAX(0,MIN($O25,moc_loi_den)-MAX($N25,moc_loi_tu))) | R25: =IF($N25="","",$P25+$Q25) | S25: =IF($N25="","",IF($Q25>0,"Blaze",IF($P25>0,"Spark",""))) | T25: =IF($N25="",0,($P25*rate_gio_bien+$Q25*rate_gio_loi)*IF($G25="Lễ",he_so_le,1)) -> 0 | U25: =IF($N25="",0,IF($S25="Blaze",bca_blaze,IF($S25="Spark",bca_spark,0))*IF($G25="Lễ",he_so_le,1)) -> 0 | V25: =ROUND($T25+$U25,0) -> 0 | W25: =IF(OR($F25<>"OPS",$H25=""),0,ROUND(IF(AND($H25>=TIME(6,0,0),$H25<TIME(8,0,0)),ops_0600_0800,IF(AND($H25>=TIME(8,0,0),$H25<TIME(18,0,0)),ops_0800_1800,IF(AND($H25>=TIME(18,0,0),$H25<TIME(22,0,0)),ops_1800_2200,IF(OR($H25>=TIME(22,0,0),$H25<TIME(1,0,0)),ops_2200_0100,IF(AND($H25>=TIME(1,0,0),$H25<TIME(6,0,0)),ops_0100_0600,0)))))+IF($G25="Lễ",ops_phu_troi_le,0),0)) -> 0 | X25: =$V25+$W25 -> 0 | Y25: =IF(OR($F25<>"OPS",$K25=""),"",IF($K25<=ops_kg_1nguoi,1,ops_nguoi_toi_da)) | Z25: =IF($D25="","",IF(AND($F25="TRUC_DEM",$R25=0),"Ca ngoài khung 22:00–06:00",IF(AND($F25="OPS",$L25<>"",$Y25<>"",$L25<$Y25),"Thiếu người so với định biên","")))
B26: =IF($D26="","",21) | E26: =IFERROR(VLOOKUP(D26,Assumption!$B$69:$C$80,2,0),"") | N26: =IF(OR($F26<>"TRUC_DEM",$H26=""),"",(HOUR($H26)+MINUTE($H26)/60)+IF((HOUR($H26)+MINUTE($H26)/60)<moc_chia_ngay,24,0)) | O26: =IF(OR($F26<>"TRUC_DEM",$I26=""),"",(HOUR($I26)+MINUTE($I26)/60)+IF((HOUR($I26)+MINUTE($I26)/60)<moc_chia_ngay,24,0)) | P26: =IF($N26="","",MAX(0,MIN($O26,moc_loi_tu)-MAX($N26,moc_dem_tu))+MAX(0,MIN($O26,moc_dem_den)-MAX($N26,moc_loi_den))) | Q26: =IF($N26="","",MAX(0,MIN($O26,moc_loi_den)-MAX($N26,moc_loi_tu))) | R26: =IF($N26="","",$P26+$Q26) | S26: =IF($N26="","",IF($Q26>0,"Blaze",IF($P26>0,"Spark",""))) | T26: =IF($N26="",0,($P26*rate_gio_bien+$Q26*rate_gio_loi)*IF($G26="Lễ",he_so_le,1)) -> 0 | U26: =IF($N26="",0,IF($S26="Blaze",bca_blaze,IF($S26="Spark",bca_spark,0))*IF($G26="Lễ",he_so_le,1)) -> 0 | V26: =ROUND($T26+$U26,0) -> 0 | W26: =IF(OR($F26<>"OPS",$H26=""),0,ROUND(IF(AND($H26>=TIME(6,0,0),$H26<TIME(8,0,0)),ops_0600_0800,IF(AND($H26>=TIME(8,0,0),$H26<TIME(18,0,0)),ops_0800_1800,IF(AND($H26>=TIME(18,0,0),$H26<TIME(22,0,0)),ops_1800_2200,IF(OR($H26>=TIME(22,0,0),$H26<TIME(1,0,0)),ops_2200_0100,IF(AND($H26>=TIME(1,0,0),$H26<TIME(6,0,0)),ops_0100_0600,0)))))+IF($G26="Lễ",ops_phu_troi_le,0),0)) -> 0 | X26: =$V26+$W26 -> 0 | Y26: =IF(OR($F26<>"OPS",$K26=""),"",IF($K26<=ops_kg_1nguoi,1,ops_nguoi_toi_da)) | Z26: =IF($D26="","",IF(AND($F26="TRUC_DEM",$R26=0),"Ca ngoài khung 22:00–06:00",IF(AND($F26="OPS",$L26<>"",$Y26<>"",$L26<$Y26),"Thiếu người so với định biên","")))
B27: =IF($D27="","",22) | E27: =IFERROR(VLOOKUP(D27,Assumption!$B$69:$C$80,2,0),"") | N27: =IF(OR($F27<>"TRUC_DEM",$H27=""),"",(HOUR($H27)+MINUTE($H27)/60)+IF((HOUR($H27)+MINUTE($H27)/60)<moc_chia_ngay,24,0)) | O27: =IF(OR($F27<>"TRUC_DEM",$I27=""),"",(HOUR($I27)+MINUTE($I27)/60)+IF((HOUR($I27)+MINUTE($I27)/60)<moc_chia_ngay,24,0)) | P27: =IF($N27="","",MAX(0,MIN($O27,moc_loi_tu)-MAX($N27,moc_dem_tu))+MAX(0,MIN($O27,moc_dem_den)-MAX($N27,moc_loi_den))) | Q27: =IF($N27="","",MAX(0,MIN($O27,moc_loi_den)-MAX($N27,moc_loi_tu))) | R27: =IF($N27="","",$P27+$Q27) | S27: =IF($N27="","",IF($Q27>0,"Blaze",IF($P27>0,"Spark",""))) | T27: =IF($N27="",0,($P27*rate_gio_bien+$Q27*rate_gio_loi)*IF($G27="Lễ",he_so_le,1)) -> 0 | U27: =IF($N27="",0,IF($S27="Blaze",bca_blaze,IF($S27="Spark",bca_spark,0))*IF($G27="Lễ",he_so_le,1)) -> 0 | V27: =ROUND($T27+$U27,0) -> 0 | W27: =IF(OR($F27<>"OPS",$H27=""),0,ROUND(IF(AND($H27>=TIME(6,0,0),$H27<TIME(8,0,0)),ops_0600_0800,IF(AND($H27>=TIME(8,0,0),$H27<TIME(18,0,0)),ops_0800_1800,IF(AND($H27>=TIME(18,0,0),$H27<TIME(22,0,0)),ops_1800_2200,IF(OR($H27>=TIME(22,0,0),$H27<TIME(1,0,0)),ops_2200_0100,IF(AND($H27>=TIME(1,0,0),$H27<TIME(6,0,0)),ops_0100_0600,0)))))+IF($G27="Lễ",ops_phu_troi_le,0),0)) -> 0 | X27: =$V27+$W27 -> 0 | Y27: =IF(OR($F27<>"OPS",$K27=""),"",IF($K27<=ops_kg_1nguoi,1,ops_nguoi_toi_da)) | Z27: =IF($D27="","",IF(AND($F27="TRUC_DEM",$R27=0),"Ca ngoài khung 22:00–06:00",IF(AND($F27="OPS",$L27<>"",$Y27<>"",$L27<$Y27),"Thiếu người so với định biên","")))
B28: =IF($D28="","",23) | E28: =IFERROR(VLOOKUP(D28,Assumption!$B$69:$C$80,2,0),"") | N28: =IF(OR($F28<>"TRUC_DEM",$H28=""),"",(HOUR($H28)+MINUTE($H28)/60)+IF((HOUR($H28)+MINUTE($H28)/60)<moc_chia_ngay,24,0)) | O28: =IF(OR($F28<>"TRUC_DEM",$I28=""),"",(HOUR($I28)+MINUTE($I28)/60)+IF((HOUR($I28)+MINUTE($I28)/60)<moc_chia_ngay,24,0)) | P28: =IF($N28="","",MAX(0,MIN($O28,moc_loi_tu)-MAX($N28,moc_dem_tu))+MAX(0,MIN($O28,moc_dem_den)-MAX($N28,moc_loi_den))) | Q28: =IF($N28="","",MAX(0,MIN($O28,moc_loi_den)-MAX($N28,moc_loi_tu))) | R28: =IF($N28="","",$P28+$Q28) | S28: =IF($N28="","",IF($Q28>0,"Blaze",IF($P28>0,"Spark",""))) | T28: =IF($N28="",0,($P28*rate_gio_bien+$Q28*rate_gio_loi)*IF($G28="Lễ",he_so_le,1)) -> 0 | U28: =IF($N28="",0,IF($S28="Blaze",bca_blaze,IF($S28="Spark",bca_spark,0))*IF($G28="Lễ",he_so_le,1)) -> 0 | V28: =ROUND($T28+$U28,0) -> 0 | W28: =IF(OR($F28<>"OPS",$H28=""),0,ROUND(IF(AND($H28>=TIME(6,0,0),$H28<TIME(8,0,0)),ops_0600_0800,IF(AND($H28>=TIME(8,0,0),$H28<TIME(18,0,0)),ops_0800_1800,IF(AND($H28>=TIME(18,0,0),$H28<TIME(22,0,0)),ops_1800_2200,IF(OR($H28>=TIME(22,0,0),$H28<TIME(1,0,0)),ops_2200_0100,IF(AND($H28>=TIME(1,0,0),$H28<TIME(6,0,0)),ops_0100_0600,0)))))+IF($G28="Lễ",ops_phu_troi_le,0),0)) -> 0 | X28: =$V28+$W28 -> 0 | Y28: =IF(OR($F28<>"OPS",$K28=""),"",IF($K28<=ops_kg_1nguoi,1,ops_nguoi_toi_da)) | Z28: =IF($D28="","",IF(AND($F28="TRUC_DEM",$R28=0),"Ca ngoài khung 22:00–06:00",IF(AND($F28="OPS",$L28<>"",$Y28<>"",$L28<$Y28),"Thiếu người so với định biên","")))
B29: =IF($D29="","",24) | E29: =IFERROR(VLOOKUP(D29,Assumption!$B$69:$C$80,2,0),"") | N29: =IF(OR($F29<>"TRUC_DEM",$H29=""),"",(HOUR($H29)+MINUTE($H29)/60)+IF((HOUR($H29)+MINUTE($H29)/60)<moc_chia_ngay,24,0)) | O29: =IF(OR($F29<>"TRUC_DEM",$I29=""),"",(HOUR($I29)+MINUTE($I29)/60)+IF((HOUR($I29)+MINUTE($I29)/60)<moc_chia_ngay,24,0)) | P29: =IF($N29="","",MAX(0,MIN($O29,moc_loi_tu)-MAX($N29,moc_dem_tu))+MAX(0,MIN($O29,moc_dem_den)-MAX($N29,moc_loi_den))) | Q29: =IF($N29="","",MAX(0,MIN($O29,moc_loi_den)-MAX($N29,moc_loi_tu))) | R29: =IF($N29="","",$P29+$Q29) | S29: =IF($N29="","",IF($Q29>0,"Blaze",IF($P29>0,"Spark",""))) | T29: =IF($N29="",0,($P29*rate_gio_bien+$Q29*rate_gio_loi)*IF($G29="Lễ",he_so_le,1)) -> 0 | U29: =IF($N29="",0,IF($S29="Blaze",bca_blaze,IF($S29="Spark",bca_spark,0))*IF($G29="Lễ",he_so_le,1)) -> 0 | V29: =ROUND($T29+$U29,0) -> 0 | W29: =IF(OR($F29<>"OPS",$H29=""),0,ROUND(IF(AND($H29>=TIME(6,0,0),$H29<TIME(8,0,0)),ops_0600_0800,IF(AND($H29>=TIME(8,0,0),$H29<TIME(18,0,0)),ops_0800_1800,IF(AND($H29>=TIME(18,0,0),$H29<TIME(22,0,0)),ops_1800_2200,IF(OR($H29>=TIME(22,0,0),$H29<TIME(1,0,0)),ops_2200_0100,IF(AND($H29>=TIME(1,0,0),$H29<TIME(6,0,0)),ops_0100_0600,0)))))+IF($G29="Lễ",ops_phu_troi_le,0),0)) -> 0 | X29: =$V29+$W29 -> 0 | Y29: =IF(OR($F29<>"OPS",$K29=""),"",IF($K29<=ops_kg_1nguoi,1,ops_nguoi_toi_da)) | Z29: =IF($D29="","",IF(AND($F29="TRUC_DEM",$R29=0),"Ca ngoài khung 22:00–06:00",IF(AND($F29="OPS",$L29<>"",$Y29<>"",$L29<$Y29),"Thiếu người so với định biên","")))
B30: =IF($D30="","",25) | E30: =IFERROR(VLOOKUP(D30,Assumption!$B$69:$C$80,2,0),"") | N30: =IF(OR($F30<>"TRUC_DEM",$H30=""),"",(HOUR($H30)+MINUTE($H30)/60)+IF((HOUR($H30)+MINUTE($H30)/60)<moc_chia_ngay,24,0)) | O30: =IF(OR($F30<>"TRUC_DEM",$I30=""),"",(HOUR($I30)+MINUTE($I30)/60)+IF((HOUR($I30)+MINUTE($I30)/60)<moc_chia_ngay,24,0)) | P30: =IF($N30="","",MAX(0,MIN($O30,moc_loi_tu)-MAX($N30,moc_dem_tu))+MAX(0,MIN($O30,moc_dem_den)-MAX($N30,moc_loi_den))) | Q30: =IF($N30="","",MAX(0,MIN($O30,moc_loi_den)-MAX($N30,moc_loi_tu))) | R30: =IF($N30="","",$P30+$Q30) | S30: =IF($N30="","",IF($Q30>0,"Blaze",IF($P30>0,"Spark",""))) | T30: =IF($N30="",0,($P30*rate_gio_bien+$Q30*rate_gio_loi)*IF($G30="Lễ",he_so_le,1)) -> 0 | U30: =IF($N30="",0,IF($S30="Blaze",bca_blaze,IF($S30="Spark",bca_spark,0))*IF($G30="Lễ",he_so_le,1)) -> 0 | V30: =ROUND($T30+$U30,0) -> 0 | W30: =IF(OR($F30<>"OPS",$H30=""),0,ROUND(IF(AND($H30>=TIME(6,0,0),$H30<TIME(8,0,0)),ops_0600_0800,IF(AND($H30>=TIME(8,0,0),$H30<TIME(18,0,0)),ops_0800_1800,IF(AND($H30>=TIME(18,0,0),$H30<TIME(22,0,0)),ops_1800_2200,IF(OR($H30>=TIME(22,0,0),$H30<TIME(1,0,0)),ops_2200_0100,IF(AND($H30>=TIME(1,0,0),$H30<TIME(6,0,0)),ops_0100_0600,0)))))+IF($G30="Lễ",ops_phu_troi_le,0),0)) -> 0 | X30: =$V30+$W30 -> 0 | Y30: =IF(OR($F30<>"OPS",$K30=""),"",IF($K30<=ops_kg_1nguoi,1,ops_nguoi_toi_da)) | Z30: =IF($D30="","",IF(AND($F30="TRUC_DEM",$R30=0),"Ca ngoài khung 22:00–06:00",IF(AND($F30="OPS",$L30<>"",$Y30<>"",$L30<$Y30),"Thiếu người so với định biên","")))
B31: =IF($D31="","",26) | E31: =IFERROR(VLOOKUP(D31,Assumption!$B$69:$C$80,2,0),"") | N31: =IF(OR($F31<>"TRUC_DEM",$H31=""),"",(HOUR($H31)+MINUTE($H31)/60)+IF((HOUR($H31)+MINUTE($H31)/60)<moc_chia_ngay,24,0)) | O31: =IF(OR($F31<>"TRUC_DEM",$I31=""),"",(HOUR($I31)+MINUTE($I31)/60)+IF((HOUR($I31)+MINUTE($I31)/60)<moc_chia_ngay,24,0)) | P31: =IF($N31="","",MAX(0,MIN($O31,moc_loi_tu)-MAX($N31,moc_dem_tu))+MAX(0,MIN($O31,moc_dem_den)-MAX($N31,moc_loi_den))) | Q31: =IF($N31="","",MAX(0,MIN($O31,moc_loi_den)-MAX($N31,moc_loi_tu))) | R31: =IF($N31="","",$P31+$Q31) | S31: =IF($N31="","",IF($Q31>0,"Blaze",IF($P31>0,"Spark",""))) | T31: =IF($N31="",0,($P31*rate_gio_bien+$Q31*rate_gio_loi)*IF($G31="Lễ",he_so_le,1)) -> 0 | U31: =IF($N31="",0,IF($S31="Blaze",bca_blaze,IF($S31="Spark",bca_spark,0))*IF($G31="Lễ",he_so_le,1)) -> 0 | V31: =ROUND($T31+$U31,0) -> 0 | W31: =IF(OR($F31<>"OPS",$H31=""),0,ROUND(IF(AND($H31>=TIME(6,0,0),$H31<TIME(8,0,0)),ops_0600_0800,IF(AND($H31>=TIME(8,0,0),$H31<TIME(18,0,0)),ops_0800_1800,IF(AND($H31>=TIME(18,0,0),$H31<TIME(22,0,0)),ops_1800_2200,IF(OR($H31>=TIME(22,0,0),$H31<TIME(1,0,0)),ops_2200_0100,IF(AND($H31>=TIME(1,0,0),$H31<TIME(6,0,0)),ops_0100_0600,0)))))+IF($G31="Lễ",ops_phu_troi_le,0),0)) -> 0 | X31: =$V31+$W31 -> 0 | Y31: =IF(OR($F31<>"OPS",$K31=""),"",IF($K31<=ops_kg_1nguoi,1,ops_nguoi_toi_da)) | Z31: =IF($D31="","",IF(AND($F31="TRUC_DEM",$R31=0),"Ca ngoài khung 22:00–06:00",IF(AND($F31="OPS",$L31<>"",$Y31<>"",$L31<$Y31),"Thiếu người so với định biên","")))
B32: =IF($D32="","",27) | E32: =IFERROR(VLOOKUP(D32,Assumption!$B$69:$C$80,2,0),"") | N32: =IF(OR($F32<>"TRUC_DEM",$H32=""),"",(HOUR($H32)+MINUTE($H32)/60)+IF((HOUR($H32)+MINUTE($H32)/60)<moc_chia_ngay,24,0)) | O32: =IF(OR($F32<>"TRUC_DEM",$I32=""),"",(HOUR($I32)+MINUTE($I32)/60)+IF((HOUR($I32)+MINUTE($I32)/60)<moc_chia_ngay,24,0)) | P32: =IF($N32="","",MAX(0,MIN($O32,moc_loi_tu)-MAX($N32,moc_dem_tu))+MAX(0,MIN($O32,moc_dem_den)-MAX($N32,moc_loi_den))) | Q32: =IF($N32="","",MAX(0,MIN($O32,moc_loi_den)-MAX($N32,moc_loi_tu))) | R32: =IF($N32="","",$P32+$Q32) | S32: =IF($N32="","",IF($Q32>0,"Blaze",IF($P32>0,"Spark",""))) | T32: =IF($N32="",0,($P32*rate_gio_bien+$Q32*rate_gio_loi)*IF($G32="Lễ",he_so_le,1)) -> 0 | U32: =IF($N32="",0,IF($S32="Blaze",bca_blaze,IF($S32="Spark",bca_spark,0))*IF($G32="Lễ",he_so_le,1)) -> 0 | V32: =ROUND($T32+$U32,0) -> 0 | W32: =IF(OR($F32<>"OPS",$H32=""),0,ROUND(IF(AND($H32>=TIME(6,0,0),$H32<TIME(8,0,0)),ops_0600_0800,IF(AND($H32>=TIME(8,0,0),$H32<TIME(18,0,0)),ops_0800_1800,IF(AND($H32>=TIME(18,0,0),$H32<TIME(22,0,0)),ops_1800_2200,IF(OR($H32>=TIME(22,0,0),$H32<TIME(1,0,0)),ops_2200_0100,IF(AND($H32>=TIME(1,0,0),$H32<TIME(6,0,0)),ops_0100_0600,0)))))+IF($G32="Lễ",ops_phu_troi_le,0),0)) -> 0 | X32: =$V32+$W32 -> 0 | Y32: =IF(OR($F32<>"OPS",$K32=""),"",IF($K32<=ops_kg_1nguoi,1,ops_nguoi_toi_da)) | Z32: =IF($D32="","",IF(AND($F32="TRUC_DEM",$R32=0),"Ca ngoài khung 22:00–06:00",IF(AND($F32="OPS",$L32<>"",$Y32<>"",$L32<$Y32),"Thiếu người so với định biên","")))
B33: =IF($D33="","",28) | E33: =IFERROR(VLOOKUP(D33,Assumption!$B$69:$C$80,2,0),"") | N33: =IF(OR($F33<>"TRUC_DEM",$H33=""),"",(HOUR($H33)+MINUTE($H33)/60)+IF((HOUR($H33)+MINUTE($H33)/60)<moc_chia_ngay,24,0)) | O33: =IF(OR($F33<>"TRUC_DEM",$I33=""),"",(HOUR($I33)+MINUTE($I33)/60)+IF((HOUR($I33)+MINUTE($I33)/60)<moc_chia_ngay,24,0)) | P33: =IF($N33="","",MAX(0,MIN($O33,moc_loi_tu)-MAX($N33,moc_dem_tu))+MAX(0,MIN($O33,moc_dem_den)-MAX($N33,moc_loi_den))) | Q33: =IF($N33="","",MAX(0,MIN($O33,moc_loi_den)-MAX($N33,moc_loi_tu))) | R33: =IF($N33="","",$P33+$Q33) | S33: =IF($N33="","",IF($Q33>0,"Blaze",IF($P33>0,"Spark",""))) | T33: =IF($N33="",0,($P33*rate_gio_bien+$Q33*rate_gio_loi)*IF($G33="Lễ",he_so_le,1)) -> 0 | U33: =IF($N33="",0,IF($S33="Blaze",bca_blaze,IF($S33="Spark",bca_spark,0))*IF($G33="Lễ",he_so_le,1)) -> 0 | V33: =ROUND($T33+$U33,0) -> 0 | W33: =IF(OR($F33<>"OPS",$H33=""),0,ROUND(IF(AND($H33>=TIME(6,0,0),$H33<TIME(8,0,0)),ops_0600_0800,IF(AND($H33>=TIME(8,0,0),$H33<TIME(18,0,0)),ops_0800_1800,IF(AND($H33>=TIME(18,0,0),$H33<TIME(22,0,0)),ops_1800_2200,IF(OR($H33>=TIME(22,0,0),$H33<TIME(1,0,0)),ops_2200_0100,IF(AND($H33>=TIME(1,0,0),$H33<TIME(6,0,0)),ops_0100_0600,0)))))+IF($G33="Lễ",ops_phu_troi_le,0),0)) -> 0 | X33: =$V33+$W33 -> 0 | Y33: =IF(OR($F33<>"OPS",$K33=""),"",IF($K33<=ops_kg_1nguoi,1,ops_nguoi_toi_da)) | Z33: =IF($D33="","",IF(AND($F33="TRUC_DEM",$R33=0),"Ca ngoài khung 22:00–06:00",IF(AND($F33="OPS",$L33<>"",$Y33<>"",$L33<$Y33),"Thiếu người so với định biên","")))
B34: =IF($D34="","",29) | E34: =IFERROR(VLOOKUP(D34,Assumption!$B$69:$C$80,2,0),"") | N34: =IF(OR($F34<>"TRUC_DEM",$H34=""),"",(HOUR($H34)+MINUTE($H34)/60)+IF((HOUR($H34)+MINUTE($H34)/60)<moc_chia_ngay,24,0)) | O34: =IF(OR($F34<>"TRUC_DEM",$I34=""),"",(HOUR($I34)+MINUTE($I34)/60)+IF((HOUR($I34)+MINUTE($I34)/60)<moc_chia_ngay,24,0)) | P34: =IF($N34="","",MAX(0,MIN($O34,moc_loi_tu)-MAX($N34,moc_dem_tu))+MAX(0,MIN($O34,moc_dem_den)-MAX($N34,moc_loi_den))) | Q34: =IF($N34="","",MAX(0,MIN($O34,moc_loi_den)-MAX($N34,moc_loi_tu))) | R34: =IF($N34="","",$P34+$Q34) | S34: =IF($N34="","",IF($Q34>0,"Blaze",IF($P34>0,"Spark",""))) | T34: =IF($N34="",0,($P34*rate_gio_bien+$Q34*rate_gio_loi)*IF($G34="Lễ",he_so_le,1)) -> 0 | U34: =IF($N34="",0,IF($S34="Blaze",bca_blaze,IF($S34="Spark",bca_spark,0))*IF($G34="Lễ",he_so_le,1)) -> 0 | V34: =ROUND($T34+$U34,0) -> 0 | W34: =IF(OR($F34<>"OPS",$H34=""),0,ROUND(IF(AND($H34>=TIME(6,0,0),$H34<TIME(8,0,0)),ops_0600_0800,IF(AND($H34>=TIME(8,0,0),$H34<TIME(18,0,0)),ops_0800_1800,IF(AND($H34>=TIME(18,0,0),$H34<TIME(22,0,0)),ops_1800_2200,IF(OR($H34>=TIME(22,0,0),$H34<TIME(1,0,0)),ops_2200_0100,IF(AND($H34>=TIME(1,0,0),$H34<TIME(6,0,0)),ops_0100_0600,0)))))+IF($G34="Lễ",ops_phu_troi_le,0),0)) -> 0 | X34: =$V34+$W34 -> 0 | Y34: =IF(OR($F34<>"OPS",$K34=""),"",IF($K34<=ops_kg_1nguoi,1,ops_nguoi_toi_da)) | Z34: =IF($D34="","",IF(AND($F34="TRUC_DEM",$R34=0),"Ca ngoài khung 22:00–06:00",IF(AND($F34="OPS",$L34<>"",$Y34<>"",$L34<$Y34),"Thiếu người so với định biên","")))
B35: =IF($D35="","",30) | E35: =IFERROR(VLOOKUP(D35,Assumption!$B$69:$C$80,2,0),"") | N35: =IF(OR($F35<>"TRUC_DEM",$H35=""),"",(HOUR($H35)+MINUTE($H35)/60)+IF((HOUR($H35)+MINUTE($H35)/60)<moc_chia_ngay,24,0)) | O35: =IF(OR($F35<>"TRUC_DEM",$I35=""),"",(HOUR($I35)+MINUTE($I35)/60)+IF((HOUR($I35)+MINUTE($I35)/60)<moc_chia_ngay,24,0)) | P35: =IF($N35="","",MAX(0,MIN($O35,moc_loi_tu)-MAX($N35,moc_dem_tu))+MAX(0,MIN($O35,moc_dem_den)-MAX($N35,moc_loi_den))) | Q35: =IF($N35="","",MAX(0,MIN($O35,moc_loi_den)-MAX($N35,moc_loi_tu))) | R35: =IF($N35="","",$P35+$Q35) | S35: =IF($N35="","",IF($Q35>0,"Blaze",IF($P35>0,"Spark",""))) | T35: =IF($N35="",0,($P35*rate_gio_bien+$Q35*rate_gio_loi)*IF($G35="Lễ",he_so_le,1)) -> 0 | U35: =IF($N35="",0,IF($S35="Blaze",bca_blaze,IF($S35="Spark",bca_spark,0))*IF($G35="Lễ",he_so_le,1)) -> 0 | V35: =ROUND($T35+$U35,0) -> 0 | W35: =IF(OR($F35<>"OPS",$H35=""),0,ROUND(IF(AND($H35>=TIME(6,0,0),$H35<TIME(8,0,0)),ops_0600_0800,IF(AND($H35>=TIME(8,0,0),$H35<TIME(18,0,0)),ops_0800_1800,IF(AND($H35>=TIME(18,0,0),$H35<TIME(22,0,0)),ops_1800_2200,IF(OR($H35>=TIME(22,0,0),$H35<TIME(1,0,0)),ops_2200_0100,IF(AND($H35>=TIME(1,0,0),$H35<TIME(6,0,0)),ops_0100_0600,0)))))+IF($G35="Lễ",ops_phu_troi_le,0),0)) -> 0 | X35: =$V35+$W35 -> 0 | Y35: =IF(OR($F35<>"OPS",$K35=""),"",IF($K35<=ops_kg_1nguoi,1,ops_nguoi_toi_da)) | Z35: =IF($D35="","",IF(AND($F35="TRUC_DEM",$R35=0),"Ca ngoài khung 22:00–06:00",IF(AND($F35="OPS",$L35<>"",$Y35<>"",$L35<$Y35),"Thiếu người so với định biên","")))
B36: =IF($D36="","",31) | E36: =IFERROR(VLOOKUP(D36,Assumption!$B$69:$C$80,2,0),"") | N36: =IF(OR($F36<>"TRUC_DEM",$H36=""),"",(HOUR($H36)+MINUTE($H36)/60)+IF((HOUR($H36)+MINUTE($H36)/60)<moc_chia_ngay,24,0)) | O36: =IF(OR($F36<>"TRUC_DEM",$I36=""),"",(HOUR($I36)+MINUTE($I36)/60)+IF((HOUR($I36)+MINUTE($I36)/60)<moc_chia_ngay,24,0)) | P36: =IF($N36="","",MAX(0,MIN($O36,moc_loi_tu)-MAX($N36,moc_dem_tu))+MAX(0,MIN($O36,moc_dem_den)-MAX($N36,moc_loi_den))) | Q36: =IF($N36="","",MAX(0,MIN($O36,moc_loi_den)-MAX($N36,moc_loi_tu))) | R36: =IF($N36="","",$P36+$Q36) | S36: =IF($N36="","",IF($Q36>0,"Blaze",IF($P36>0,"Spark",""))) | T36: =IF($N36="",0,($P36*rate_gio_bien+$Q36*rate_gio_loi)*IF($G36="Lễ",he_so_le,1)) -> 0 | U36: =IF($N36="",0,IF($S36="Blaze",bca_blaze,IF($S36="Spark",bca_spark,0))*IF($G36="Lễ",he_so_le,1)) -> 0 | V36: =ROUND($T36+$U36,0) -> 0 | W36: =IF(OR($F36<>"OPS",$H36=""),0,ROUND(IF(AND($H36>=TIME(6,0,0),$H36<TIME(8,0,0)),ops_0600_0800,IF(AND($H36>=TIME(8,0,0),$H36<TIME(18,0,0)),ops_0800_1800,IF(AND($H36>=TIME(18,0,0),$H36<TIME(22,0,0)),ops_1800_2200,IF(OR($H36>=TIME(22,0,0),$H36<TIME(1,0,0)),ops_2200_0100,IF(AND($H36>=TIME(1,0,0),$H36<TIME(6,0,0)),ops_0100_0600,0)))))+IF($G36="Lễ",ops_phu_troi_le,0),0)) -> 0 | X36: =$V36+$W36 -> 0 | Y36: =IF(OR($F36<>"OPS",$K36=""),"",IF($K36<=ops_kg_1nguoi,1,ops_nguoi_toi_da)) | Z36: =IF($D36="","",IF(AND($F36="TRUC_DEM",$R36=0),"Ca ngoài khung 22:00–06:00",IF(AND($F36="OPS",$L36<>"",$Y36<>"",$L36<$Y36),"Thiếu người so với định biên","")))
B37: =IF($D37="","",32) | E37: =IFERROR(VLOOKUP(D37,Assumption!$B$69:$C$80,2,0),"") | N37: =IF(OR($F37<>"TRUC_DEM",$H37=""),"",(HOUR($H37)+MINUTE($H37)/60)+IF((HOUR($H37)+MINUTE($H37)/60)<moc_chia_ngay,24,0)) | O37: =IF(OR($F37<>"TRUC_DEM",$I37=""),"",(HOUR($I37)+MINUTE($I37)/60)+IF((HOUR($I37)+MINUTE($I37)/60)<moc_chia_ngay,24,0)) | P37: =IF($N37="","",MAX(0,MIN($O37,moc_loi_tu)-MAX($N37,moc_dem_tu))+MAX(0,MIN($O37,moc_dem_den)-MAX($N37,moc_loi_den))) | Q37: =IF($N37="","",MAX(0,MIN($O37,moc_loi_den)-MAX($N37,moc_loi_tu))) | R37: =IF($N37="","",$P37+$Q37) | S37: =IF($N37="","",IF($Q37>0,"Blaze",IF($P37>0,"Spark",""))) | T37: =IF($N37="",0,($P37*rate_gio_bien+$Q37*rate_gio_loi)*IF($G37="Lễ",he_so_le,1)) -> 0 | U37: =IF($N37="",0,IF($S37="Blaze",bca_blaze,IF($S37="Spark",bca_spark,0))*IF($G37="Lễ",he_so_le,1)) -> 0 | V37: =ROUND($T37+$U37,0) -> 0 | W37: =IF(OR($F37<>"OPS",$H37=""),0,ROUND(IF(AND($H37>=TIME(6,0,0),$H37<TIME(8,0,0)),ops_0600_0800,IF(AND($H37>=TIME(8,0,0),$H37<TIME(18,0,0)),ops_0800_1800,IF(AND($H37>=TIME(18,0,0),$H37<TIME(22,0,0)),ops_1800_2200,IF(OR($H37>=TIME(22,0,0),$H37<TIME(1,0,0)),ops_2200_0100,IF(AND($H37>=TIME(1,0,0),$H37<TIME(6,0,0)),ops_0100_0600,0)))))+IF($G37="Lễ",ops_phu_troi_le,0),0)) -> 0 | X37: =$V37+$W37 -> 0 | Y37: =IF(OR($F37<>"OPS",$K37=""),"",IF($K37<=ops_kg_1nguoi,1,ops_nguoi_toi_da)) | Z37: =IF($D37="","",IF(AND($F37="TRUC_DEM",$R37=0),"Ca ngoài khung 22:00–06:00",IF(AND($F37="OPS",$L37<>"",$Y37<>"",$L37<$Y37),"Thiếu người so với định biên","")))
B38: =IF($D38="","",33) | E38: =IFERROR(VLOOKUP(D38,Assumption!$B$69:$C$80,2,0),"") | N38: =IF(OR($F38<>"TRUC_DEM",$H38=""),"",(HOUR($H38)+MINUTE($H38)/60)+IF((HOUR($H38)+MINUTE($H38)/60)<moc_chia_ngay,24,0)) | O38: =IF(OR($F38<>"TRUC_DEM",$I38=""),"",(HOUR($I38)+MINUTE($I38)/60)+IF((HOUR($I38)+MINUTE($I38)/60)<moc_chia_ngay,24,0)) | P38: =IF($N38="","",MAX(0,MIN($O38,moc_loi_tu)-MAX($N38,moc_dem_tu))+MAX(0,MIN($O38,moc_dem_den)-MAX($N38,moc_loi_den))) | Q38: =IF($N38="","",MAX(0,MIN($O38,moc_loi_den)-MAX($N38,moc_loi_tu))) | R38: =IF($N38="","",$P38+$Q38) | S38: =IF($N38="","",IF($Q38>0,"Blaze",IF($P38>0,"Spark",""))) | T38: =IF($N38="",0,($P38*rate_gio_bien+$Q38*rate_gio_loi)*IF($G38="Lễ",he_so_le,1)) -> 0 | U38: =IF($N38="",0,IF($S38="Blaze",bca_blaze,IF($S38="Spark",bca_spark,0))*IF($G38="Lễ",he_so_le,1)) -> 0 | V38: =ROUND($T38+$U38,0) -> 0 | W38: =IF(OR($F38<>"OPS",$H38=""),0,ROUND(IF(AND($H38>=TIME(6,0,0),$H38<TIME(8,0,0)),ops_0600_0800,IF(AND($H38>=TIME(8,0,0),$H38<TIME(18,0,0)),ops_0800_1800,IF(AND($H38>=TIME(18,0,0),$H38<TIME(22,0,0)),ops_1800_2200,IF(OR($H38>=TIME(22,0,0),$H38<TIME(1,0,0)),ops_2200_0100,IF(AND($H38>=TIME(1,0,0),$H38<TIME(6,0,0)),ops_0100_0600,0)))))+IF($G38="Lễ",ops_phu_troi_le,0),0)) -> 0 | X38: =$V38+$W38 -> 0 | Y38: =IF(OR($F38<>"OPS",$K38=""),"",IF($K38<=ops_kg_1nguoi,1,ops_nguoi_toi_da)) | Z38: =IF($D38="","",IF(AND($F38="TRUC_DEM",$R38=0),"Ca ngoài khung 22:00–06:00",IF(AND($F38="OPS",$L38<>"",$Y38<>"",$L38<$Y38),"Thiếu người so với định biên","")))
B39: =IF($D39="","",34) | E39: =IFERROR(VLOOKUP(D39,Assumption!$B$69:$C$80,2,0),"") | N39: =IF(OR($F39<>"TRUC_DEM",$H39=""),"",(HOUR($H39)+MINUTE($H39)/60)+IF((HOUR($H39)+MINUTE($H39)/60)<moc_chia_ngay,24,0)) | O39: =IF(OR($F39<>"TRUC_DEM",$I39=""),"",(HOUR($I39)+MINUTE($I39)/60)+IF((HOUR($I39)+MINUTE($I39)/60)<moc_chia_ngay,24,0)) | P39: =IF($N39="","",MAX(0,MIN($O39,moc_loi_tu)-MAX($N39,moc_dem_tu))+MAX(0,MIN($O39,moc_dem_den)-MAX($N39,moc_loi_den))) | Q39: =IF($N39="","",MAX(0,MIN($O39,moc_loi_den)-MAX($N39,moc_loi_tu))) | R39: =IF($N39="","",$P39+$Q39) | S39: =IF($N39="","",IF($Q39>0,"Blaze",IF($P39>0,"Spark",""))) | T39: =IF($N39="",0,($P39*rate_gio_bien+$Q39*rate_gio_loi)*IF($G39="Lễ",he_so_le,1)) -> 0 | U39: =IF($N39="",0,IF($S39="Blaze",bca_blaze,IF($S39="Spark",bca_spark,0))*IF($G39="Lễ",he_so_le,1)) -> 0 | V39: =ROUND($T39+$U39,0) -> 0 | W39: =IF(OR($F39<>"OPS",$H39=""),0,ROUND(IF(AND($H39>=TIME(6,0,0),$H39<TIME(8,0,0)),ops_0600_0800,IF(AND($H39>=TIME(8,0,0),$H39<TIME(18,0,0)),ops_0800_1800,IF(AND($H39>=TIME(18,0,0),$H39<TIME(22,0,0)),ops_1800_2200,IF(OR($H39>=TIME(22,0,0),$H39<TIME(1,0,0)),ops_2200_0100,IF(AND($H39>=TIME(1,0,0),$H39<TIME(6,0,0)),ops_0100_0600,0)))))+IF($G39="Lễ",ops_phu_troi_le,0),0)) -> 0 | X39: =$V39+$W39 -> 0 | Y39: =IF(OR($F39<>"OPS",$K39=""),"",IF($K39<=ops_kg_1nguoi,1,ops_nguoi_toi_da)) | Z39: =IF($D39="","",IF(AND($F39="TRUC_DEM",$R39=0),"Ca ngoài khung 22:00–06:00",IF(AND($F39="OPS",$L39<>"",$Y39<>"",$L39<$Y39),"Thiếu người so với định biên","")))
B40: =IF($D40="","",35) | E40: =IFERROR(VLOOKUP(D40,Assumption!$B$69:$C$80,2,0),"") | N40: =IF(OR($F40<>"TRUC_DEM",$H40=""),"",(HOUR($H40)+MINUTE($H40)/60)+IF((HOUR($H40)+MINUTE($H40)/60)<moc_chia_ngay,24,0)) | O40: =IF(OR($F40<>"TRUC_DEM",$I40=""),"",(HOUR($I40)+MINUTE($I40)/60)+IF((HOUR($I40)+MINUTE($I40)/60)<moc_chia_ngay,24,0)) | P40: =IF($N40="","",MAX(0,MIN($O40,moc_loi_tu)-MAX($N40,moc_dem_tu))+MAX(0,MIN($O40,moc_dem_den)-MAX($N40,moc_loi_den))) | Q40: =IF($N40="","",MAX(0,MIN($O40,moc_loi_den)-MAX($N40,moc_loi_tu))) | R40: =IF($N40="","",$P40+$Q40) | S40: =IF($N40="","",IF($Q40>0,"Blaze",IF($P40>0,"Spark",""))) | T40: =IF($N40="",0,($P40*rate_gio_bien+$Q40*rate_gio_loi)*IF($G40="Lễ",he_so_le,1)) -> 0 | U40: =IF($N40="",0,IF($S40="Blaze",bca_blaze,IF($S40="Spark",bca_spark,0))*IF($G40="Lễ",he_so_le,1)) -> 0 | V40: =ROUND($T40+$U40,0) -> 0 | W40: =IF(OR($F40<>"OPS",$H40=""),0,ROUND(IF(AND($H40>=TIME(6,0,0),$H40<TIME(8,0,0)),ops_0600_0800,IF(AND($H40>=TIME(8,0,0),$H40<TIME(18,0,0)),ops_0800_1800,IF(AND($H40>=TIME(18,0,0),$H40<TIME(22,0,0)),ops_1800_2200,IF(OR($H40>=TIME(22,0,0),$H40<TIME(1,0,0)),ops_2200_0100,IF(AND($H40>=TIME(1,0,0),$H40<TIME(6,0,0)),ops_0100_0600,0)))))+IF($G40="Lễ",ops_phu_troi_le,0),0)) -> 0 | X40: =$V40+$W40 -> 0 | Y40: =IF(OR($F40<>"OPS",$K40=""),"",IF($K40<=ops_kg_1nguoi,1,ops_nguoi_toi_da)) | Z40: =IF($D40="","",IF(AND($F40="TRUC_DEM",$R40=0),"Ca ngoài khung 22:00–06:00",IF(AND($F40="OPS",$L40<>"",$Y40<>"",$L40<$Y40),"Thiếu người so với định biên","")))
